Workbook
Name DCAC: #REF!
Name DCAC: #REF!
Name DCAC: #REF!
Name DD: #REF!
Name DD: #REF!
Name DD: #REF!
Name DDD: #REF!
Name DDD: #REF!
Name DDD: #REF!
Name DDDA: #REF!
Name DDDA: #REF!
Name DDDA: #REF!
Name DDDD: #REF!
Name DDDD: #REF!
Name DDDD: #REF!
Name Declaraciones: #REF!
Name Declaraciones: #REF!
Name Declaraciones: #REF!
Name ded: #REF!
Name ded: #REF!
Name ded: #REF!
Name Diarios: #REF!
Name Diarios: #REF!
Name Diarios: #REF!
Name EE: #REF!
Name EE: #REF!
Name EE: #REF!
Name EEE: #REF!
Name EEE: #REF!
Name EEE: #REF!
Name Excel_BuiltIn__FilterDatabase_2: #REF!
Name Excel_BuiltIn__FilterDatabase_2: #REF!
Name Excel_BuiltIn__FilterDatabase_2: #REF!
Name HDSADUA: #REF!
Name HDSADUA: #REF!
Name HDSADUA: #REF!
Name HI: #REF!
Name HI: #REF!
Name HI: #REF!
Name HOJA: #REF!
Name HOJA: #REF!
Name HOJA: #REF!
Name INVERSIONES: #REF!
Name INVERSIONES: #REF!
Name INVERSIONES: #REF!
Name JFJ: #REF!
Name JFJ: #REF!
Name JFJ: #REF!
Name JJJ: #REF!
Name JJJ: #REF!
Name JJJ: #REF!
Name NIIF1: #REF!
Name NIIF1: #REF!
Name QQ: #REF!
Name QQ: #REF!
Name QQ: #REF!
Name sggs: #REF!
Name sggs: #REF!
Name sggs: #REF!
Name SSS: #REF!

Sheet DATOS
A1: TODOS LOS VALORES SE DIGITAN POSITIVOS EXEPTO DEPRECIACIONES
A3: PUC SOLO UNA GUIA NO ES IGUAL EN TODOS | C3: 2025 | E3: 2024
A4: 1 | B4: ACTIVO | C4: =+C5+C10+C18+C25+C37+C39+C41 -> 2353833.4 | E4: =+E5+E10+E18+E25+E37+E39+E41 -> 2947382.3
A5: 11 | B5: EFECTIVO Y EQUIV. AL EFECTIVO | C5: =SUM(C6:C9) -> 139451.13 | E5: =SUM(E6:E9) -> 316343.36
A6: 1105 | B6: CAJA | C6: =+(SUMIF('BCE 2026'!A:A,DATOS!A6,'BCE 2026'!I:I))/1000 -> 65577.056 | E6: =+(SUMIF('BCE 2025'!A:A,DATOS!A6,'BCE 2025'!I:I))/1000 -> 214238.89 | G6: EMPRESA | H6: GRUPO DE LOLITA S.A.S
A7: 1110 | B7: BANCOS | C7: =+(SUMIF('BCE 2026'!A:A,DATOS!A7,'BCE 2026'!I:I))/1000 -> 40333.952 | E7: =+(SUMIF('BCE 2025'!A:A,DATOS!A7,'BCE 2025'!I:I))/1000 -> 81215.599 | G7: NIT | H7: NIT: 900.307.969-5
A8: 1120 | B8: CUENTAS DE AHORROS | C8: =+(SUMIF('BCE 2026'!A:A,DATOS!A8,'BCE 2026'!I:I))/1000 -> 0 | E8: =+(SUMIF('BCE 2025'!A:A,DATOS!A8,'BCE 2025'!I:I))/1000 -> 18936.424 | G8: FECHA DE CORTE | H8: A 30 de Junio de 2026 y 2025
A9: 1130 | B9: INVERSIONES A LA VISTA | C9: =+(SUMIF('BCE 2026'!A:A,DATOS!A9,'BCE 2026'!I:I))/1000 -> 33540.119 | E9: =+(SUMIF('BCE 2025'!A:A,DATOS!A9,'BCE 2025'!I:I))/1000 -> 1952.4422 | G9: MES | H9: 6
A10: 13 | B10: CUENTAS POR COBRAR | C10: =SUM(C11:C17) -> 764459.77 | E10: =SUM(E11:E17) -> 232927.86 | G10: FECHA E.F | H10: 2026-06
A11: 1305 | B11: CLIENTES | C11: =+(SUMIF('BCE 2026'!A:A,DATOS!A11,'BCE 2026'!I:I))/1000 -> 6216.1707 | E11: =+(SUMIF('BCE 2025'!A:A,DATOS!A11,'BCE 2025'!I:I))/1000 -> 6031.8756 | G11: FECHA E.F COMP | H11: 2025-06
A12: 1330 | B12: ANTICIPOS Y AVANCES | C12: =+(SUMIF('BCE 2026'!A:A,DATOS!A12,'BCE 2026'!I:I))/1000 -> 648905.4 | E12: =+(SUMIF('BCE 2025'!A:A,DATOS!A12,'BCE 2025'!I:I))/1000 -> 184646.96 | G12: Rep Legal | H12: Fernando Filevich Leiva
A13: 1365 | B13: CUENTAS POR COBRAR A TRABAJADORES | C13: =+(SUMIF('BCE 2026'!A:A,DATOS!A13,'BCE 2026'!I:I))/1000 -> 852.794 | E13: =+(SUMIF('BCE 2025'!A:A,DATOS!A13,'BCE 2025'!I:I))/1000 -> 1997.585 | G13: Cedula Rep Legal | H13: C.E 274.113
A14: 1380 | B14: DEUDORES VARIOS | C14: =+(SUMIF('BCE 2026'!A:A,DATOS!A14,'BCE 2026'!I:I))/1000 -> 108485.41 | E14: =+(SUMIF('BCE 2025'!A:A,DATOS!A14,'BCE 2025'!I:I))/1000 -> 40251.44 | G14: Contador | H14: Leidy Yasmin Gomez Toro
A15: 13 | B15: OTRAS | C15: 0 | E15: 0 | G15: T.P: | H15: TP: 318364-T
A16: 1390 | B16: DETERIORO | C16: =+(SUMIF('BCE 2026'!A:A,DATOS!A16,'BCE 2026'!I:I))/1000 -> 0 | E16: =+(SUMIF('BCE 2025'!A:A,DATOS!A16,'BCE 2025'!I:I))/1000 -> 0 | G16: Revisor Fiscal | H16: Fabian Elver Hernandez Garcia
A17: 1399 | B17: PROVISIONES CADENAS | C17: =+(SUMIF('BCE 2026'!A:A,DATOS!A17,'BCE 2026'!I:I))/1000 -> 0 | E17: =+(SUMIF('BCE 2025'!A:A,DATOS!A17,'BCE 2025'!I:I))/1000 -> 0 | G17: T.P: | H17: 333711-T
A18: 14 | B18: INVENTARIOS | C18: =SUM(C19:C24) -> 9295.325 | E18: =SUM(E19:E24) -> 81849.588 | G18: TASA DE MERCADO | H18: 0.01
A19: 1405 | B19: MATERIAS PRIMAS | C19: =+(SUMIF('BCE 2026'!A:A,DATOS!A19,'BCE 2026'!I:I))/1000 -> 0 | E19: =+(SUMIF('BCE 2025'!A:A,DATOS!A19,'BCE 2025'!I:I))/1000 -> 0
A20: 1410 | B20: PRODUCTOS EN PROCESO | C20: =+(SUMIF('BCE 2026'!A:A,DATOS!A20,'BCE 2026'!I:I))/1000 -> 0 | E20: =+(SUMIF('BCE 2025'!A:A,DATOS!A20,'BCE 2025'!I:I))/1000 -> 0
A21: 1430 | B21: PRODUCTO TERMINADO | C21: =+(SUMIF('BCE 2026'!A:A,DATOS!A21,'BCE 2026'!I:I))/1000 -> 0 | E21: =+(SUMIF('BCE 2025'!A:A,DATOS!A21,'BCE 2025'!I:I))/1000 -> 0
A22: 1435 | B22: MERCANCIA NO FABRICADA | C22: =+(SUMIF('BCE 2026'!A:A,DATOS!A22,'BCE 2026'!I:I))/1000 -> 9295.325 | E22: =+(SUMIF('BCE 2025'!A:A,DATOS!A22,'BCE 2025'!I:I))/1000 -> 81849.588
A23: 143530 | B23: ANTICIPOS INVENTARIOS | C23: =+(SUMIF('BCE 2026'!A:A,DATOS!A23,'BCE 2026'!I:I))/1000 -> 0 | E23: =+(SUMIF('BCE 2025'!A:A,DATOS!A23,'BCE 2025'!I:I))/1000 -> 0
A24: 1497 | B24: DETERIORO | C24: =+(SUMIF('BCE 2026'!A:A,DATOS!A24,'BCE 2026'!I:I))/1000 -> 0 | E24: =+(SUMIF('BCE 2025'!A:A,DATOS!A24,'BCE 2025'!I:I))/1000 -> 0
A25: 15 | B25: PROPIEDAD PLANTA Y EQUIPO | C25: =SUM(C26:C36) -> 538379.65 | E25: =SUM(E26:E36) -> 2028379.9
A26: 1510 | B26: MEJORAS A PROPIEDADES AJENAS | C26: =+(SUMIF('BCE 2026'!A:A,DATOS!A26,'BCE 2026'!I:I))/1000 -> 0 | E26: =+(SUMIF('BCE 2025'!A:A,DATOS!A26,'BCE 2025'!I:I))/1000 -> 355856.13
A27: 151630 | B27: CONSTRUCCIONES | C27: =+(SUMIF('BCE 2026'!A:A,DATOS!A27,'BCE 2026'!I:I))/1000 -> 0 | E27: =+(SUMIF('BCE 2025'!A:A,DATOS!A27,'BCE 2025'!I:I))/1000 -> 1286225.2
A28: 151692 | B28: DEPRECIACION CONSTRUCCIONES | C28: =+((SUMIF('BCE 2026'!A:A,DATOS!A28,'BCE 2026'!I:I))/1000)/2 -> 0 | E28: =+(SUMIF('BCE 2025'!A:A,DATOS!A28,'BCE 2025'!I:I))/1000/2 -> -145249.72
A29: 152001 | B29: MAQUINARIA Y EQUIPO | C29: =+((SUMIF('BCE 2026'!A:A,DATOS!A29,'BCE 2026'!I:I))/1000)+((SUMIF('BCE 2026'!A:A,152006,'BCE 2026'!I:I))/1000)+((SUMIF('BCE 2026'!A:A,152010,'BCE 2026'!I:I))/1000)+(((SUMIF('BCE 2026'!A:A,152045,'BCE 2026'!I:I))/2)/1000)+(((SUMIF('BCE 2026'!A:A,152015,'BCE 2026'!I:I)))/1000) -> 534086.15 | E29: =+((SUMIF('BCE 2025'!A:A,DATOS!A29,'BCE 2025'!I:I))/1000)+((SUMIF('BCE 2025'!A:A,152006,'BCE 2025'!I:I))/1000)+((SUMIF('BCE 2025'!A:A,152010,'BCE 2025'!I:I))/1000)+(((SUMIF('BCE 2025'!A:A,152045,'BCE 2025'!I:I))/1000)/2) -> 455026.46
A30: 152092 | B30: DEPRECIACION MAQUINARIA Y EQUIPO | C30: =+((SUMIF('BCE 2026'!A:A,DATOS!A30,'BCE 2026'!I:I))/1000)/2 -> 0 | E30: =+(SUMIF('BCE 2025'!A:A,DATOS!A30,'BCE 2025'!I:I))/1000/2 -> -103612.51
A31: 152405 | B31: EQUIPO DE OFICINA | C31: =+((SUMIF('BCE 2026'!A:A,DATOS!A31,'BCE 2026'!I:I))/1000)+((SUMIF('BCE 2026'!A:A,152410,'BCE 2026'!I:I))/1000) -> 0 | E31: =+((SUMIF('BCE 2025'!A:A,DATOS!A31,'BCE 2025'!I:I))/1000)+((SUMIF('BCE 2025'!A:A,152410,'BCE 2025'!I:I))/1000) -> 210990.46
A32: 152492 | B32: DEPRECIACION EQUIPO DE OFICINA | C32: =+((SUMIF('BCE 2026'!A:A,DATOS!A32,'BCE 2026'!I:I))/1000)/2 -> 0 | E32: =+(SUMIF('BCE 2025'!A:A,DATOS!A32,'BCE 2025'!I:I))/1000/2 -> -45495.23
A33: 152805 | B33: EQUIPO COMPUTAC.Y COMUNICAC. | C33: =+(SUMIF('BCE 2026'!A:A,DATOS!A33,'BCE 2026'!I:I))/1000+(SUMIF('BCE 2026'!A:A,152810,'BCE 2026'!I:I))/1000 -> 4293.503 | E33: =+(SUMIF('BCE 2025'!A:A,DATOS!A33,'BCE 2025'!I:I))/1000+(SUMIF('BCE 2025'!A:A,152810,'BCE 2025'!I:I))/1000 -> 42702.049
A34: 152892 | B34: DEPRECIACION EQUIPO COMPUTAC. | C34: =+((SUMIF('BCE 2026'!A:A,DATOS!A34,'BCE 2026'!I:I))/1000)/2 -> 0 | E34: =+(SUMIF('BCE 2025'!A:A,DATOS!A34,'BCE 2025'!I:I))/1000/2 -> -28062.93
A35: 154005 | B35: EQUIPO DE TRANSPORTE | C35: =+(SUMIF('BCE 2026'!A:A,DATOS!A35,'BCE 2026'!I:I))/1000 -> 0 | E35: =+(SUMIF('BCE 2025'!A:A,DATOS!A35,'BCE 2025'!I:I))/1000 -> 0
A36: 154090 | B36: DEPRECIACION EQUIPO DE TRANSPORTE | C36: =+((SUMIF('BCE 2026'!A:A,DATOS!A36,'BCE 2026'!I:I))/1000)/2 -> 0 | E36: =+(SUMIF('BCE 2025'!A:A,DATOS!A36,'BCE 2025'!I:I))/1000/2 -> 0
A37: 16 | B37: INTANGIBLES | C37: =SUM(C38) -> 764766.8 | E37: =SUM(E38) -> 220000
A38: 16 | B38: LICENCIAS | C38: =+(SUMIF('BCE 2026'!A:A,DATOS!A38,'BCE 2026'!I:I))/1000 -> 764766.8 | E38: =+(SUMIF('BCE 2025'!A:A,DATOS!A38,'BCE 2025'!I:I))/1000 -> 220000
A39: 17 | B39: OTROS ACTIVOS | C39: =SUM(C40) -> 0 | E39: =SUM(E40) -> 0
A40: 17 | B40: GASTOS PAGADOS POR ANTICIPADO | C40: =+(SUMIF('BCE 2026'!A:A,DATOS!A40,'BCE 2026'!I:I))/1000 -> 0 | E40: =+(SUMIF('BCE 2025'!A:A,DATOS!A40,'BCE 2025'!I:I))/1000 -> 0
A41: 19 | B41: ACTIVOS POR IMPUESTOS | C41: =+C42+C43 -> 137480.76 | E41: =+E42+E43 -> 67881.501
...

Sheet E.R.I.MES
A2: =+DATOS!H6 -> GRUPO DE LOLITA S.A.S
A3: =+DATOS!H7 -> NIT: 900.307.969-5
A4: ESTADO DE RESULTADOS INTEGRAL MENSUAL
A5: =+DATOS!H8 -> A 30 de Junio de 2026 y 2025
A6: (Cifras Expresadas en Miles de Pesos Colombianos)
C9: NOTAS | D9: =+DATOS!H10 -> 2026-06 | E9: A.V | G9: =+DATOS!H11 -> 2025-06 | H9: A.V | I9: VARIACION | J9: A.H
A10: Ingresos de Manufactura | C10: 12 | D10: =+DATOS!C91 -> 0 | E10: =+D10/$D$13 -> 0 | G10: =+DATOS!F91 -> 0 | H10: =+G10/$G$13 -> 0 | I10: =+D10-G10 -> 0 | J10: =IFERROR(I10/G10,100%)*OR(IF(D10-G10=0,(0%),+I10/G10)) -> 0
A11: Ingresos de Comercializacion | D11: =+DATOS!C92 -> 344178.47 | E11: =+D11/$D$13 -> 1.0026618 | G11: =+DATOS!F92 -> 515898.99 | H11: =+G11/$G$13 -> 1.0013648 | I11: =+D11-G11 -> -171720.52 | J11: =IFERROR(I11/G11,100%)*OR(IF(D11-G11=0,(0%),+I11/G11)) -> -0.33285687
A12: Devoluciones en ventas | D12: =-DATOS!C93-DATOS!C94 -> -913.697 | E12: =+D12/$D$13 -> -0.002661785 | G12: =-DATOS!F93-DATOS!F94 -> -703.161 | H12: =+G12/$G$13 -> -0.0013648422 | I12: =+D12-G12 -> -210.536 | J12: =IFERROR(I12/G12,100%)*OR(IF(D12-G12=0,(0%),+I12/G12)) -> 0.29941365
A13: Ingresos netos | D13: =SUM(D10:D12) -> 343264.77 | E13: =+D13/$D$13 -> 1 | G13: =SUM(G10:G12) -> 515195.83 | H13: =+G13/$G$13 -> 1 | I13: =+D13-G13 -> -171931.06 | J13: =IFERROR(I13/G13,100%)*OR(IF(D13-G13=0,(0%),+I13/G13)) -> -0.33371982
A15: Costo de ventas | D15: =SUM(D16:D17) -> -155609.25 | E15: =+D15/$D$13 -> -0.45332135 | G15: =SUM(G16:G17) -> -221817 | H15: =+G15/$G$13 -> -0.43054891 | I15: =+D15-G15 -> 66207.752 | J15: =IFERROR(I15/G15,100%)*OR(IF(D15-G15=0,(0%),+I15/G15)) -> -0.29847916
A16: Costo de Manufactura | D16: =-+DATOS!C165 -> -155609.25 | E16: =+D16/(D10+D12) -> 170.30728 | G16: =-DATOS!F165 -> -221817 | H16: =+G16/(G10+G12) -> 315.45692 | I16: =+D16-G16 -> 66207.752 | J16: =IFERROR(I16/G16,100%)*OR(IF(D16-G16=0,(0%),+I16/G16)) -> -0.29847916
A17: Costo de Comercializacion | D17: =-+DATOS!C166 -> 0 | E17: =+D17/$D$11 -> 0 | G17: =-DATOS!F166 -> 0 | H17: =+G17/$G$11 -> 0 | I17: =+D17-G17 -> 0 | J17: =IFERROR(I17/G17,100%)*OR(IF(D17-G17=0,(0%),+I17/G17)) -> 0
A19: GANANCIA BRUTA | D19: =+D13+D15 -> 187655.52 | E19: =+D19/$D$13 -> 0.54667865 | G19: =+G13+G15 -> 293378.83 | H19: =+G19/$G$13 -> 0.56945109 | I19: =+D19-G19 -> -105723.31 | J19: =IFERROR(I19/G19,100%)*OR(IF(D19-G19=0,(0%),+I19/G19)) -> -0.36036447
A21: Otros Ingresos | C21: 13 | D21: =SUM(D22:D29) -> 2043.652 | E21: =+D21/$D$13 -> 0.0059535734 | G21: =SUM(G22:G29) -> 1944.1296 | H21: =+G21/$G$13 -> 0.0037735741 | I21: =+D21-G21 -> 99.52235 | J21: =+I21/G21 -> 0.05119121
A22: Otras Ventas | D22: =+DATOS!C96 -> 0 | E22: =+D22/$D$13 -> 0 | G22: =+DATOS!F96 -> 0 | H22: =+G22/$G$13 -> 0 | I22: =+D22-G22 -> 0 | J22: =+I22/G22 -> #DIV/0!
A23: Arriendos | D23: =+DATOS!C97 -> 0 | E23: =+D23/$D$13 -> 0 | G23: =+DATOS!F97 -> 0 | H23: =+G23/$G$13 -> 0 | I23: =+D23-G23 -> 0 | J23: =+I23/G23 -> #DIV/0!
A24: Comisiones | D24: =+DATOS!C98 -> 0 | E24: =+D24/$D$13 -> 0 | G24: =+DATOS!F98 -> 0 | H24: =+G24/$G$13 -> 0 | I24: =+D24-G24 -> 0 | J24: =+I24/G24 -> #DIV/0!
A25: Honorarios | D25: =+DATOS!C99 -> 0 | E25: =+D25/$D$13 -> 0 | G25: =+DATOS!F99 -> 0 | H25: =+G25/$G$13 -> 0 | I25: =+D25-G25 -> 0 | J25: =+I25/G25 -> #DIV/0!
A26: Servicios | D26: =+DATOS!C100 -> 0 | E26: =+D26/$D$13 -> 0 | G26: =+DATOS!F100 -> 1421.3146 | H26: =+G26/$G$13 -> 0.0027587852 | I26: =+D26-G26 -> -1421.3146 | J26: =+I26/G26 -> -1
A27: Recuperacion de costos y gastos | D27: =+DATOS!C101 -> 2.35 | E27: =+D27/$D$13 -> 6.8460273e-06 | G27: =+DATOS!F101 -> 3.6 | H27: =+G27/$G$13 -> 6.9876342e-06 | I27: =+D27-G27 -> -1.25 | J27: =+I27/G27 -> -0.34722222
A28: Indemnizaciones | D28: =+DATOS!C102 -> 1587.204 | E28: =+D28/$D$13 -> 0.0046238476 | G28: =+DATOS!F102 -> 0 | H28: =+G28/$G$13 -> 0 | I28: =+D28-G28 -> 1587.204 | J28: =+I28/G28 -> #DIV/0!
A29: Diversos | D29: =+DATOS!C103 -> 454.098 | E29: =+D29/$D$13 -> 0.0013228797 | G29: =+DATOS!F103 -> 519.215 | H29: =+G29/$G$13 -> 0.0010078012 | I29: =+D29-G29 -> -65.117 | J29: =+I29/G29 -> -0.12541433
A30: Gastos de Ventas | D30: =SUM(D31:D51) -> -162440.53 | E30: =+D30/$D$13 -> -0.47322227 | G30: =SUM(G31:G51) -> -287674.29 | H30: =+G30/$G$13 -> -0.55837854 | I30: =+D30-G30 -> 125233.76 | J30: =IFERROR(I30/G30,100%)*OR(IF(D30-G30=0,(0%),+I30/G30)) -> -0.43533177
A31: Aportes sobre la nomina | D31: =-+DATOS!C126 -> -10707.489 | E31: =+D31/$D$13 -> -0.03119309 | G31: =-DATOS!F126 -> -11909.829 | H31: =+G31/$G$13 -> -0.023117091 | I31: =+D31-G31 -> 1202.34 | J31: =IFERROR(I31/G31,100%)*OR(IF(D31-G31=0,(0%),+I31/G31)) -> -0.10095359
A32: Gastos de personal | D32: =-DATOS!C127 -> -77098.253 | E32: =+D32/$D$13 -> -0.22460287 | G32: =-DATOS!F127 -> -90565.838 | H32: =+G32/$G$13 -> -0.17578915 | I32: =+D32-G32 -> 13467.585 | J32: =IFERROR(I32/G32,100%)*OR(IF(D32-G32=0,(0%),+I32/G32)) -> -0.14870491
A33: Honorarios | D33: =-DATOS!C128 -> -9704.53 | E33: =+D33/$D$13 -> -0.028271267 | G33: =-DATOS!F128 -> -28024.563 | H33: =+G33/$G$13 -> -0.054395943 | I33: =+D33-G33 -> 18320.033 | J33: =IFERROR(I33/G33,100%)*OR(IF(D33-G33=0,(0%),+I33/G33)) -> -0.65371342
A34: Impuestos | D34: =-DATOS!C129 -> -4735.1879 | E34: =+D34/$D$13 -> -0.013794564 | G34: =-DATOS!F129 -> -7525.4209 | H34: =+G34/$G$13 -> -0.014606913 | I34: =+D34-G34 -> 2790.233 | J34: =IFERROR(I34/G34,100%)*OR(IF(D34-G34=0,(0%),+I34/G34)) -> -0.37077434
A35: Arrendamientos | D35: =-DATOS!C130 -> -25291.885 | E35: =+D35/$D$13 -> -0.073680398 | G35: =-DATOS!F130 -> -65083.597 | H35: =+G35/$G$13 -> -0.12632788 | I35: =+D35-G35 -> 39791.712 | J35: =IFERROR(I35/G35,100%)*OR(IF(D35-G35=0,(0%),+I35/G35)) -> -0.61139387
A36: Contribuciones | D36: =-DATOS!C131 -> -2085.522 | E36: =+D36/$D$13 -> -0.0060755492 | G36: =-DATOS!F131 -> -12011.502 | H36: =+G36/$G$13 -> -0.02331444 | I36: =+D36-G36 -> 9925.98 | J36: =IFERROR(I36/G36,100%)*OR(IF(D36-G36=0,(0%),+I36/G36)) -> -0.82637292
A37: Seguros | D37: =-DATOS!C132 -> 0 | E37: =+D37/$D$13 -> 0 | G37: =-DATOS!F132 -> 0 | H37: =+G37/$G$13 -> 0 | I37: =+D37-G37 -> 0 | J37: =IFERROR(I37/G37,100%)*OR(IF(D37-G37=0,(0%),+I37/G37)) -> 0
A38: Servicios | D38: =-DATOS!C133 -> -11683.576 | E38: =+D38/$D$13 -> -0.03403663 | G38: =-DATOS!F133 -> -39982.011 | H38: =+G38/$G$13 -> -0.077605463 | I38: =+D38-G38 -> 28298.435 | J38: =IFERROR(I38/G38,100%)*OR(IF(D38-G38=0,(0%),+I38/G38)) -> -0.70777918
A39: Fletes | D39: =-DATOS!C134 -> -3171.519 | E39: =+D39/$D$13 -> -0.009239279 | G39: =-DATOS!F134 -> -3353.115 | H39: =+G39/$G$13 -> -0.0065084281 | I39: =+D39-G39 -> 181.596 | J39: =IFERROR(I39/G39,100%)*OR(IF(D39-G39=0,(0%),+I39/G39)) -> -0.054157403
A40: Otro | D40: =-DATOS!C135 -> -9257.236 | E40: =+D40/$D$13 -> -0.026968209 | G40: =-DATOS!F135 -> -19715.306 | H40: =+G40/$G$13 -> -0.038267596 | I40: =+D40-G40 -> 10458.07 | J40: =IFERROR(I40/G40,100%)*OR(IF(D40-G40=0,(0%),+I40/G40)) -> -0.53045436
A41: Gastos Legales | D41: =-DATOS!C136 -> -12.1 | E41: =+D41/$D$13 -> -3.5249758e-05 | G41: =-DATOS!F136 -> 0 | H41: =+G41/$G$13 -> 0 | I41: =+D41-G41 -> -12.1 | J41: =IFERROR(I41/G41,100%)*OR(IF(D41-G41=0,(0%),+I41/G41)) -> #DIV/0!
A42: Mantenimientos | D42: =-DATOS!C137 -> -1670 | E42: =+D42/$D$13 -> -0.0048650492 | G42: =-DATOS!F137 -> -2795.343 | H42: =+G42/$G$13 -> -0.0054257873 | I42: =+D42-G42 -> 1125.343 | J42: =IFERROR(I42/G42,100%)*OR(IF(D42-G42=0,(0%),+I42/G42)) -> -0.40257779
A43: Adecuaciones | D43: =-DATOS!C138 -> 0 | E43: =+D43/$D$13 -> 0 | G43: =-DATOS!F138 -> -1387 | H43: =+G43/$G$13 -> -0.0026921802 | I43: =+D43-G43 -> 1387 | J43: =IFERROR(I43/G43,100%)*OR(IF(D43-G43=0,(0%),+I43/G43)) -> -1
... A51: Deterioro | D51: =-DATOS!C146 -> -622.982 | E51: =+D51/$D$13 -> -0.0018148731 | G51: =-DATOS!F146 -> -456.141 | H51: =+G51/$G$13 -> -0.00088537402 | I51: =+D51-G51 -> -166.841 | J51: =IFERROR(I51/G51,100%)*OR(IF(D51-G51=0,(0%),+I51/G51)) -> 0.36576629
A52: Gastos de Administracion | C52: 14 | D52: =SUM(D53:D67) -> 0 | E52: =+D52/$D$13 -> 0 | G52: =SUM(G53:G67) -> 0 | H52: =+G52/$G$13 -> 0 | I52: =+D52-G52 -> 0 | J52: =IFERROR(I52/G52,100%)*OR(IF(D52-G52=0,(0%),+I52/G52)) -> 0
A53: Aportes sobre la nomina | D53: =-+DATOS!C110 -> 0 | E53: =+D53/$D$13 -> 0 | G53: =-DATOS!F110 -> 0 | H53: =+G53/$G$13 -> 0 | I53: =+D53-G53 -> 0 | J53: =IFERROR(I53/G53,100%)*OR(IF(D53-G53=0,(0%),+I53/G53)) -> 0
...

Sheet E.R.I.ACUMULADO
A2: =+DATOS!H6 -> GRUPO DE LOLITA S.A.S
A3: =+DATOS!H7 -> NIT: 900.307.969-5
A4: ESTADO DE RESULTADOS INTEGRAL ACUMULADO
A5: =+DATOS!H8 -> A 30 de Junio de 2026 y 2025
A6: (Cifras Expresadas en Miles de Pesos Colombianos)
C9: NOTAS | D9: =+DATOS!H10 -> 2026-06 | E9: A.V | G9: =+DATOS!H11 -> 2025-06 | H9: A.V | I9: VARIACION | J9: A.H
A10: Ingresos de Manufactura | C10: 12 | D10: =+DATOS!D91 -> 0 | E10: =+D10/$D$13 -> 0 | G10: =+DATOS!G91 -> 0 | H10: =+G10/$G$13 -> 0 | I10: =+D10-G10 -> 0 | J10: =IFERROR(I10/G10,100%)*OR(IF(D10-G10=0,(0%),+I10/I10)) -> 0
A11: Ingresos de Comercializacion | D11: =+DATOS!D92 -> 2120978.2 | E11: =+D11/$D$13 -> 1.0020531 | G11: =+DATOS!G92 -> 2943371.7 | H11: =+G11/$G$13 -> 1.0015103 | I11: =+D11-G11 -> -822393.43 | J11: =IFERROR(I11/G11,100%)*OR(IF(D11-G11=0,(0%),+I11/G11)) -> -0.27940523
A12: Devoluciones en ventas | D12: =-DATOS!D93-DATOS!D94 -> -4345.604 | E12: =+D12/$D$13 -> -0.0020530743 | G12: =-DATOS!G93-DATOS!G94 -> -4438.5587 | H12: =+G12/$G$13 -> -0.0015102619 | I12: =+D12-G12 -> 92.95472 | J12: 0
A13: Ingresos netos | D13: =SUM(D10:D12) -> 2116632.6 | E13: =+D13/$D$13 -> 1 | G13: =SUM(G10:G12) -> 2938933.1 | H13: =+G13/$G$13 -> 1 | I13: =+D13-G13 -> -822300.47 | J13: =IFERROR(I13/G13,100%)*OR(IF(D13-G13=0,(0%),+I13/G13)) -> -0.27979557
A15: Costo de ventas | D15: =SUM(D16:D17) -> -956551.84 | E15: =+D15/$D$13 -> -0.45192152 | G15: =SUM(G16:G17) -> -1241064.9 | H15: =+G15/$G$13 -> -0.42228418 | I15: =+D15-G15 -> 284513.1 | J15: =IFERROR(I15/G15,100%)*OR(IF(D15-G15=0,(0%),+I15/G15)) -> -0.22924917
A16: Costo de Manufactura | D16: =-DATOS!D165 -> -956551.84 | E16: =+D16/(D10+D12) -> 220.11942 | G16: =-DATOS!G165 -> -1241064.9 | H16: =+G16/(G10+G12) -> 279.6099 | I16: =+D16-G16 -> 284513.1 | J16: =IFERROR(I16/G16,100%)*OR(IF(D16-G16=0,(0%),+I16/G16)) -> -0.22924917
A17: Costo de Comercializacion | D17: =-DATOS!D166 -> 0 | E17: =+D17/$D$11 -> 0 | G17: =-DATOS!G166 -> 0 | H17: =+G17/$G$11 -> 0 | I17: =+D17-G17 -> 0 | J17: =IFERROR(I17/G17,100%)*OR(IF(D17-G17=0,(0%),+I17/G17)) -> 0
A19: GANANCIA BRUTA | D19: =+D13+D15 -> 1160080.8 | E19: =+D19/$D$13 -> 0.54807848 | G19: =+G13+G15 -> 1697868.2 | H19: =+G19/$G$13 -> 0.57771582 | I19: =+D19-G19 -> -537787.37 | J19: =IFERROR(I19/G19,100%)*OR(IF(D19-G19=0,(0%),+I19/G19)) -> -0.31674271
A21: Otros Ingresos | C21: 13 | D21: =SUM(D22:D29) -> 11029.217 | E21: =+D21/$D$13 -> 0.0052107373 | G21: =SUM(G22:G29) -> 9958.0801 | H21: =+G21/$G$13 -> 0.0033883317 | I21: =+D21-G21 -> 1071.1367 | J21: =+I21/G21 -> 0.10756457
A22: Otras Ventas | D22: =+DATOS!D96 -> 0 | E22: =+D22/$D$13 -> 0 | G22: =+DATOS!G96 -> 0 | H22: =+G22/$G$13 -> 0 | I22: =+D22-G22 -> 0 | J22: =+I22/G22 -> #DIV/0!
A23: Arriendos | D23: =+DATOS!D97 -> 0 | E23: =+D23/$D$13 -> 0 | G23: =+DATOS!G97 -> 0 | H23: =+G23/$G$13 -> 0 | I23: =+D23-G23 -> 0 | J23: =+I23/G23 -> #DIV/0!
A24: Comisiones | D24: =+DATOS!D98 -> 0 | E24: =+D24/$D$13 -> 0 | G24: =+DATOS!G98 -> 0 | H24: =+G24/$G$13 -> 0 | I24: =+D24-G24 -> 0 | J24: =+I24/G24 -> #DIV/0!
A25: Honorarios | D25: =+DATOS!D99 -> 0 | E25: =+D25/$D$13 -> 0 | G25: =+DATOS!G99 -> 0 | H25: =+G25/$G$13 -> 0 | I25: =+D25-G25 -> 0 | J25: =+I25/G25 -> #DIV/0!
A26: Servicios | D26: =+DATOS!D100 -> 16.80672 | E26: =+D26/$D$13 -> 7.9403103e-06 | G26: =+DATOS!G100 -> 4160.5028 | H26: =+G26/$G$13 -> 0.0014156507 | I26: =+D26-G26 -> -4143.6961 | J26: =+I26/G26 -> -0.99596041
A27: Recuperacion de costos y gastos | D27: =+DATOS!D101 -> 13.847 | E27: =+D27/$D$13 -> 6.5419949e-06 | G27: =+DATOS!G101 -> 19.563 | H27: =+G27/$G$13 -> 6.6564972e-06 | I27: =+D27-G27 -> -5.716 | J27: =+I27/G27 -> -0.29218423
A28: Indemnizaciones | D28: =+DATOS!D102 -> 7831.45 | E28: =+D28/$D$13 -> 0.0036999571 | G28: =+DATOS!G102 -> 1051.249 | H28: =+G28/$G$13 -> 0.00035769749 | I28: =+D28-G28 -> 6780.201 | J28: =+I28/G28 -> 6.4496623
A29: Diversos | D29: =+DATOS!D103 -> 3167.113 | E29: =+D29/$D$13 -> 0.0014962979 | G29: =+DATOS!G103 -> 4726.7653 | H29: =+G29/$G$13 -> 0.0016083269 | I29: =+D29-G29 -> -1559.6523 | J29: =+I29/G29 -> -0.32996186
A30: Gastos de Ventas | D30: =SUM(D31:D51) -> -1008903.7 | E30: =+D30/$D$13 -> -0.4766551 | G30: =SUM(G31:G51) -> -1570195 | H30: =+G30/$G$13 -> -0.53427382 | I30: =+D30-G30 -> 561291.27 | J30: =IFERROR(I30/G30,100%)*OR(IF(D30-G30=0,(0%),+I30/G30)) -> -0.35746596
A31: Aportes sobre la nomina | D31: =-DATOS!D126 -> -63233.053 | E31: =+D31/$D$13 -> -0.029874364 | G31: =-DATOS!G126 -> -66610.884 | H31: =+G31/$G$13 -> -0.022664988 | I31: =+D31-G31 -> 3377.831 | J31: =IFERROR(I31/G31,100%)*OR(IF(D31-G31=0,(0%),+I31/G31)) -> -0.050709896
A32: Gastos de personal | D32: =-DATOS!D127 -> -464409.86 | E32: =+D32/$D$13 -> -0.21940976 | G32: =-DATOS!G127 -> -493062.06 | H32: =+G32/$G$13 -> -0.16776907 | I32: =+D32-G32 -> 28652.206 | J32: =IFERROR(I32/G32,100%)*OR(IF(D32-G32=0,(0%),+I32/G32)) -> -0.058110749
A33: Honorarios | D33: =-DATOS!D128 -> -39255.786 | E33: =+D33/$D$13 -> -0.018546339 | G33: =-DATOS!G128 -> -121030.17 | H33: =+G33/$G$13 -> -0.04118167 | I33: =+D33-G33 -> 81774.387 | J33: =IFERROR(I33/G33,100%)*OR(IF(D33-G33=0,(0%),+I33/G33)) -> -0.6756529
A34: Impuestos | D34: =-DATOS!D129 -> -25132.84 | E34: =+D34/$D$13 -> -0.011873974 | G34: =-DATOS!G129 -> -51562.601 | H34: =+G34/$G$13 -> -0.017544666 | I34: =+D34-G34 -> 26429.761 | J34: =IFERROR(I34/G34,100%)*OR(IF(D34-G34=0,(0%),+I34/G34)) -> -0.51257618
A35: Arrendamientos | D35: =-DATOS!D130 -> -151823.94 | E35: =+D35/$D$13 -> -0.071729001 | G35: =-DATOS!G130 -> -394048.55 | H35: =+G35/$G$13 -> -0.13407878 | I35: =+D35-G35 -> 242224.61 | J35: =IFERROR(I35/G35,100%)*OR(IF(D35-G35=0,(0%),+I35/G35)) -> -0.61470752
A36: Contribuciones | D36: =-DATOS!D131 -> -12891.579 | E36: =+D36/$D$13 -> -0.0060906077 | G36: =-DATOS!G131 -> -73967.344 | H36: =+G36/$G$13 -> -0.025168094 | I36: =+D36-G36 -> 61075.765 | J36: =IFERROR(I36/G36,100%)*OR(IF(D36-G36=0,(0%),+I36/G36)) -> -0.82571256
A37: Seguros | D37: =-DATOS!D132 -> -2014.388 | E37: =+D37/$D$13 -> -0.00095169467 | G37: =-DATOS!G132 -> -10729.971 | H37: =+G37/$G$13 -> -0.0036509749 | I37: =+D37-G37 -> 8715.583 | J37: =IFERROR(I37/G37,100%)*OR(IF(D37-G37=0,(0%),+I37/G37)) -> -0.81226529
A38: Servicios | D38: =-DATOS!D133 -> -70819.082 | E38: =+D38/$D$13 -> -0.033458372 | G38: =-DATOS!G133 -> -165220.58 | H38: =+G38/$G$13 -> -0.056217876 | I38: =+D38-G38 -> 94401.496 | J38: =IFERROR(I38/G38,100%)*OR(IF(D38-G38=0,(0%),+I38/G38)) -> -0.57136646
A39: Fletes | D39: =-DATOS!D134 -> -22943.238 | E39: =+D39/$D$13 -> -0.010839499 | G39: =-DATOS!G134 -> -21747.765 | H39: =+G39/$G$13 -> -0.0073998843 | I39: =+D39-G39 -> -1195.473 | J39: =IFERROR(I39/G39,100%)*OR(IF(D39-G39=0,(0%),+I39/G39)) -> 0.054969924
A40: Otro | D40: =-DATOS!D135 -> -94757.329 | E40: =+D40/$D$13 -> -0.044767962 | G40: =-DATOS!G135 -> -98550.995 | H40: =+G40/$G$13 -> -0.033532915 | I40: =+D40-G40 -> 3793.666 | J40: =IFERROR(I40/G40,100%)*OR(IF(D40-G40=0,(0%),+I40/G40)) -> -0.038494446
A41: Gastos Legales | D41: =-DATOS!D136 -> -4667.6 | E41: =+D41/$D$13 -> -0.0022052008 | G41: =-DATOS!G136 -> -6130.119 | H41: =+G41/$G$13 -> -0.0020858314 | I41: =+D41-G41 -> 1462.519 | J41: =IFERROR(I41/G41,100%)*OR(IF(D41-G41=0,(0%),+I41/G41)) -> -0.23857922
A42: Mantenimientos | D42: =-DATOS!D137 -> -8123.857 | E42: =+D42/$D$13 -> -0.0038381044 | G42: =-DATOS!G137 -> -15052.446 | H42: =+G42/$G$13 -> -0.0051217382 | I42: =+D42-G42 -> 6928.589 | J42: =IFERROR(I42/G42,100%)*OR(IF(D42-G42=0,(0%),+I42/G42)) -> -0.46029655
... A51: Deterioro | D51: =-DATOS!D146 -> -1144.366 | E51: =+D51/$D$13 -> -0.00054065405 | G51: =-DATOS!G146 -> -5886.857 | H51: =+G51/$G$13 -> -0.0020030592 | I51: =+D51-G51 -> 4742.491 | J51: =IFERROR(I51/G51,100%)*OR(IF(D51-G51=0,(0%),+I51/G51)) -> -0.80560663
A52: Gastos de Administracion | C52: 14 | D52: =SUM(D53:D67) -> 0 | E52: =+D52/$D$13 -> 0 | G52: =SUM(G53:G67) -> 0 | H52: =+G52/$G$13 -> 0 | I52: =+D52-G52 -> 0 | J52: =IFERROR(I52/G52,100%)*OR(IF(D52-G52=0,(0%),+I52/G52)) -> 0
A53: Aportes sobre la nomina | D53: =-DATOS!D110 -> 0 | E53: =+D53/$D$13 -> 0 | G53: =-DATOS!G110 -> 0 | H53: =+G53/$G$13 -> 0 | I53: =+D53-G53 -> 0 | J53: =IFERROR(I53/G53,100%)*OR(IF(D53-G53=0,(0%),+I53/G53)) -> 0
A54: Gastos de personal | D54: =-DATOS!D111 -> 0 | E54: =+D54/$D$13 -> 0 | G54: =-DATOS!G111 -> 0 | H54: =+G54/$G$13 -> 0 | I54: =+D54-G54 -> 0 | J54: =IFERROR(I54/G54,100%)*OR(IF(D54-G54=0,(0%),+I54/G54)) -> 0
...

Sheet ESF=BALANCE
B2: =+DATOS!H6 -> GRUPO DE LOLITA S.A.S
B3: =+DATOS!H7 -> NIT: 900.307.969-5
B4: ESTADO DE SITUACIÒN FINANCIERA
B5: =+DATOS!H8 -> A 30 de Junio de 2026 y 2025
B6: (Cifras expresadas en Miles de pesos colombianos)
B9: ACTIVOS | D9: =+DATOS!H10 -> 2026-06 | G9: =+DATOS!H11 -> 2025-06 | J9: PASIVOS | L9: =+D9 -> 2026-06 | O9: =+G9 -> 2025-06
J10: =IFERROR(I10/G10,100%)*OR(IF(D10-G10=0,(0%),+I10/I10)) -> 0
B11: Activos Corrientes | J11: Pasivos Corrientes
B12: Efectivo y Equivalentes de Efectivo | D12: =SUM(D13:D16) -> 139451.13 | E12: =+D12/$D$71 -> 0.059244263 | G12: =SUM(G13:G16) -> 316343.36 | H12: =+G12/$G$71 -> 0.10733028 | J12: Obligaciones Financieras | L12: =+L13 -> 0 | M12: =+L12/$L$71 -> 0 | O12: =+O13 -> 0 | P12: =+O12/$O$71 -> 0
B13: Caja | D13: =+DATOS!C6 -> 65577.056 | E13: =+D13/$D$71 -> 0.027859684 | G13: =+DATOS!E6 -> 214238.89 | H13: =+G13/$G$71 -> 0.072687854 | J13: Sobregiro | L13: =+DATOS!C47 -> 0 | M13: =+L13/$L$71 -> 0 | O13: =+DATOS!E47 -> 0 | P13: =+O13/$O$71 -> 0
B14: Bancos | D14: =+DATOS!C7 -> 40333.952 | E14: =+D14/$D$71 -> 0.017135432 | G14: =+DATOS!E7 -> 81215.599 | H14: =+G14/$G$71 -> 0.027555163
B15: Cuentas de ahorros | D15: =+DATOS!C8 -> 0 | E15: =+D15/$D$71 -> 0 | G15: =+DATOS!E8 -> 18936.424 | H15: =+G15/$G$71 -> 0.006424828 | J15: Cuentas Por Pagar | L15: =SUM(L16:L17) -> 134879.89 | M15: =+L15/$L$71 -> 0.062993439 | O15: =SUM(O16:O17) -> 204376.72 | P15: =+O15/$O$71 -> 0.069341774
B16: Inversiones a la vista | D16: =+DATOS!C9 -> 33540.119 | E16: =+D16/$D$71 -> 0.014249147 | G16: =+DATOS!E9 -> 1952.4422 | H16: =+G16/$G$71 -> 0.00066243264 | J16: Proveedores | L16: =+DATOS!C51 -> 113653.71 | M16: =+L16/$L$71 -> 0.0530801 | O16: =+DATOS!E51 -> 198797.21 | P16: =+O16/$O$71 -> 0.067448737
J17: Costos y gastos por pagar | L17: =+DATOS!C54 -> 21226.182 | M17: =+L17/$L$71 -> 0.0099133398 | O17: =+DATOS!E54 -> 5579.505 | P17: =+O17/$O$71 -> 0.0018930375
B18: Activos por Impuesto | D18: =+D19 -> 137480.76 | E18: =+D18/$D$71 -> 0.058407173 | G18: =+G19 -> 67881.501 | H18: =+G18/$G$71 -> 0.023031115
B19: Anticipo de Impuestos | D19: =+DATOS!C43 -> 137480.76 | E19: =+D19/$D$71 -> 0.058407173 | G19: =+DATOS!E43 -> 67881.501 | H19: =+G19/$G$71 -> 0.023031115 | J19: Pasivo Por Impuestos | L19: =SUM(L20:L23) -> 177433.75 | M19: =+L19/$L$71 -> 0.082867522 | O19: =SUM(O20:O23) -> 126229.07 | P19: =+O19/$O$71 -> 0.042827519
J20: Impuesto sobre las ventas | L20: =+DATOS!C63 -> 133798.75 | M20: =+L20/$L$71 -> 0.062488511 | O20: =+DATOS!E63 -> 73042.873 | P20: =+O20/$O$71 -> 0.024782287
B21: Cuentas Por Cobrar | D21: =+SUM(D22:D28) -> 764459.77 | E21: =+D21/$D$71 -> 0.32477225 | G21: =+SUM(G22:G28) -> 232927.86 | H21: =+G21/$G$71 -> 0.079028726 | J21: Retenciòn en la fuente | L21: =+DATOS!C62 -> 9299 | M21: =+L21/$L$71 -> 0.0043429453 | O21: =+DATOS!E62 -> 26515 | P21: =+O21/$O$71 -> 0.0089961185
B22: Clientes | D22: =+DATOS!C11 -> 6216.1707 | E22: =+D22/$D$71 -> 0.0026408711 | G22: =+DATOS!E11 -> 6031.8756 | H22: =+G22/$G$71 -> 0.0020465196 | J22: Otros | L22: =+DATOS!C64 -> 0 | M22: =+L22/$L$71 -> 0 | O22: =+DATOS!E64 -> 0 | P22: =+O22/$O$71 -> 0
B23: Anticipos y avances | D23: =+DATOS!C12 -> 648905.4 | E23: =+D23/$D$71 -> 0.27568025 | G23: =+DATOS!E12 -> 184646.96 | H23: =+G23/$G$71 -> 0.062647783 | J23: Impuesto a las ganancias | L23: =+DATOS!C60 -> 34336 | M23: =+L23/$L$71 -> 0.016036065 | O23: =+DATOS!E60 -> 26671.196 | P23: =+O23/$O$71 -> 0.0090491133
B24: A empleados | D24: =+DATOS!C13 -> 852.794 | E24: =+D24/$D$71 -> 0.00036230006 | G24: =+DATOS!E13 -> 1997.585 | H24: =+G24/$G$71 -> 0.00067774887
B25: Deudores varios | D25: =+DATOS!C14 -> 108485.41 | E25: =+D25/$D$71 -> 0.046088824 | G25: =+DATOS!E14 -> 40251.44 | H25: =+G25/$G$71 -> 0.013656674 | J25: Beneficios a Empleados | L25: =+SUM(L26:L31) -> 49498.343 | M25: =+L25/$L$71 -> 0.023117389 | O25: =+SUM(O26:O31) -> 79649.727 | P25: =+O25/$O$71 -> 0.027023888
B26: Otros | D26: =+DATOS!C15 -> 0 | E26: =+D26/$D$71 -> 0 | G26: =+DATOS!E15 -> 0 | J26: Salarios por pagar | L26: =+DATOS!C66 -> 0 | M26: =+L26/$L$71 -> 0 | O26: =+DATOS!E66 -> 428.45 | P26: =+O26/$O$71 -> 0.00014536628
B27: Provisiones | D27: =+DATOS!C17 -> 0 | E27: =+D27/$D$71 -> 0 | G27: =+DATOS!E17 -> 0 | H27: =+G27/$G$71 -> 0 | J27: Cesantias | L27: =+DATOS!C68 -> 27389.114 | M27: =+L27/$L$71 -> 0.012791636 | O27: =+DATOS!E68 -> 28954.985 | P27: =+O27/$O$71 -> 0.0098239667
B28: Deterioro | D28: =+DATOS!C16 -> 0 | E28: =+D28/$D$71 -> 0 | G28: =+DATOS!E16 -> 0 | H28: =+G28/$G$71 -> 0 | J28: Intereses sobre cesantias | L28: =+DATOS!C69 -> 1547.99 | M28: =+L28/$L$71 -> 0.00072296333 | O28: =+DATOS!E69 -> 1946.014 | P28: =+O28/$O$71 -> 0.00066025165
J29: Prima de servicios | L29: =+DATOS!C71 -> 0 | M29: =+L29/$L$71 -> 0 | O29: =+DATOS!E71 -> -189.477 | P29: =+O29/$O$71 -> -6.4286538e-05
B30: Inventarios | D30: =+SUM(D31:D36) -> 9295.325 | E30: =+D30/$D$71 -> 0.0039490156 | G30: =+SUM(G31:G36) -> 81849.588 | H30: =+G30/$G$71 -> 0.027770266 | J30: Vacaciones consolidadas | L30: =+DATOS!C67+DATOS!C70 -> 20561.239 | M30: =+L30/$L$71 -> 0.0096027892 | O30: =+DATOS!E67+DATOS!E70 -> 27113.622 | P30: =+O30/$O$71 -> 0.0091992214
B31: Materias primas | D31: =+DATOS!C19 -> 0 | E31: =+D31/$D$71 -> 0 | G31: =+DATOS!E19 -> 0 | H31: =+G31/$G$71 -> 0 | J31: Retenciones y aportes de nomina | L31: =+DATOS!C72 -> 0 | M31: =+L31/$L$71 -> 0 | O31: =+DATOS!E72 -> 21396.133 | P31: =+O31/$O$71 -> 0.0072593682
B32: Productos en proceso | D32: =+DATOS!C20 -> 0 | E32: =+D32/$D$71 -> 0 | G32: =+DATOS!E20 -> 0 | H32: =+G32/$G$71 -> 0
B33: Producto terminado | D33: =+DATOS!C21 -> 0 | E33: =+D33/$D$71 -> 0 | G33: =+DATOS!E21 -> 0 | H33: =+G33/$G$71 -> 0 | J33: Otros Pasivos | L33: =+SUM(L34:L36) -> 11007.863 | M33: =+L33/$L$71 -> 0.0051410418 | O33: =+SUM(O34:O36) -> 36360.174 | P33: =+O33/$O$71 -> 0.01233643
B34: Mercancia no fabricada por la empresa | D34: =+DATOS!C22 -> 9295.325 | E34: =+D34/$D$71 -> 0.0039490156 | G34: =+DATOS!E22 -> 81849.588 | H34: =+G34/$G$71 -> 0.027770266 | J34: Anticipos y avances | L34: =+DATOS!C74 -> 812.017 | M34: =+L34/$L$71 -> 0.00037923921 | O34: =+DATOS!E74 -> 3711.9331 | P34: =+O34/$O$71 -> 0.0012593999
B35: Anticipos | D35: =+DATOS!C23 -> 0 | G35: =+DATOS!E23 -> 0 | J35: Ingresos para terceros | L35: =+DATOS!C75 -> 0 | M35: =+L35/$L$71 -> 0 | O35: =+DATOS!E75 -> 0 | P35: =+O35/$O$71 -> 0
B36: Deterioro | D36: =+DATOS!C24 -> 0 | E36: =+D36/$D$71 -> 0 | G36: =+DATOS!E24 -> 0 | H36: =+G36/$G$71 -> 0 | J36: Provision impuestos muniipales | L36: =+DATOS!C76 -> 10195.846 | M36: =+L36/$L$71 -> 0.0047618026 | O36: =+DATOS!E76 -> 32648.241 | P36: =+O36/$O$71 -> 0.01107703
B38: Total Activos Corrientes | D38: =+D30+D21+D12+D18 -> 1050687 | E38: =+D38/$D$71 -> 0.4463727 | G38: =+G30+G21+G12+G18 -> 699002.31 | H38: =+G38/$G$71 -> 0.23716038 | J38: Total Pasivos Corrientes | L38: =+L25+L19+L15+L33+L12 -> 372819.85 | M38: =+L38/$L$71 -> 0.17411939 | O38: =+O25+O19+O15+O33+O12 -> 446615.68 | P38: =+O38/$O$71 -> 0.15152961 | S38: =+D38/7 -> 150098.14
J40: Pasivos No Corrientes
J41: Obligaciones Financieras | L41: =SUM(L42:L44) -> 792798.79 | M41: =+L41/$L$71 -> 0.37026367 | O41: =SUM(O42:O44) -> 330619.2 | P41: =+O41/$O$71 -> 0.11217384
J42: Bancos Nacionales | L42: =+DATOS!C48 -> 54203.787 | M42: =+L42/$L$71 -> 0.025314989 | O42: =+DATOS!E48 -> 302913.67 | P42: =+O42/$O$71 -> 0.1027738
J43: Contratos de arrendamiento Leasing | L43: =+DATOS!C49 -> 738595.01 | M43: =+L43/$L$71 -> 0.34494868 | O43: =+DATOS!E49 -> 3419.9981 | P43: =+O43/$O$71 -> 0.0011603511
J44: Otras obligaciones | L44: =+DATOS!C50 -> 0 | M44: =+L44/$L$71 -> 0 | O44: =+DATOS!E50 -> 24285.53 | P44: =+O44/$O$71 -> 0.0082396947
B45: Activos No Corrientes
...

Sheet EFE
A1: =+'E.R.I.ACUMULADO'!A2 -> GRUPO DE LOLITA S.A.S
A2: =+'E.R.I.ACUMULADO'!A3 -> NIT: 900.307.969-5
A3: ESTADO DE FLUJOS DE EFECTIVO
A4: =+'E.R.I.ACUMULADO'!A6 -> (Cifras Expresadas en Miles de Pesos Colombianos)
A5: A DICIEMBRE 31 DE 2021
A7: FLUJOS DE FONDOS PROVENIENTES DE LAS ACTIVIDADES DE OPERACIÓN
A8: Utilidad neta del Ejercicio | C8: =+'E.R.I.ACUMULADO'!D109 -> 56988.014
A10: Mas o (Menos) Partidas que no afectaron el Efectivo
A11: Depreciación de Activos Fijos | C11: =-('ESF=BALANCE'!D57-'ESF=BALANCE'!G57) -> -322420.39
A12: Amortización | C12: 0
A14: Subtotal Efectivo Generado por la Operación | C14: =SUM(C8:C13) -> -265432.37
A15: CAMBIOS EN ACTIVO Y PASIVO OPERACIONAL
A16: (Aumento) Disminución en Deudores | C16: =+'ESF=BALANCE'!G21-'ESF=BALANCE'!D21 -> -531531.91
A17: (Aumento) Disminución en Inventarios | C17: =+'ESF=BALANCE'!G30-'ESF=BALANCE'!D30 -> 72554.263
A18: (Aumento) Disminución en Activo por Impuestos | C18: =+'ESF=BALANCE'!G18-'ESF=BALANCE'!D18 -> -69599.257
A19: (Aumento) Disminución en Activo por Impuestos Diferidos | C19: =+'ESF=BALANCE'!G66-'ESF=BALANCE'!D66 -> 0
A20: Aumento (Disminucion) Obligac. Financieras | C20: =+'ESF=BALANCE'!L41-'ESF=BALANCE'!O41 -> 462179.6
A21: Aumento (Disminución) de Cuentas por Pagar | C21: =+'ESF=BALANCE'!L15-'ESF=BALANCE'!O15 -> -69496.824
A22: Aumento (Disminución) de Pasivos por Impuestos ctes | C22: =+'ESF=BALANCE'!L19-'ESF=BALANCE'!O19 -> 51204.683
A23: Aumento (Disminución) de Beneficios a Empleados | C23: =+'ESF=BALANCE'!L25-'ESF=BALANCE'!O25 -> -30151.384
A24: Aumento (Disminución) de otros pasivos | C24: =+'ESF=BALANCE'!L33-'ESF=BALANCE'!O33+'ESF=BALANCE'!L46-'ESF=BALANCE'!O46+'ESF=BALANCE'!L13-'ESF=BALANCE'!O13 -> -29470.539
A25: TOTAL EFECTIVO PROVISTO POR LAS ACTIVIDADES DE OPERACIÓN | C25: =SUM(C14:C24) -> -409743.74
A26: FLUJOS DE EFECTIVO PROVENIENTE DE LAS ACTIVIDADES DE INVERSION
A27: (Aumento) Disminución de Plantaciones Agricolas (activo Biologico) | C27: 0
A28: (Aumento) Disminución Prop. Planta y Equipo | C28: =+'ESF=BALANCE'!G52+'ESF=BALANCE'!G53+'ESF=BALANCE'!G54+'ESF=BALANCE'!G55+'ESF=BALANCE'!G56+'ESF=BALANCE'!G60-'ESF=BALANCE'!D52-'ESF=BALANCE'!D53-'ESF=BALANCE'!D54-'ESF=BALANCE'!D55-'ESF=BALANCE'!D56-'ESF=BALANCE'!D60 -> 911797.75
A29: TOTAL EFECTIVO USADO EN INVERSION | C29: =SUM(C27:C28) -> 911797.75
A30: FLUJOS DE EFECTIVO PROVENIENTE DE LAS ACTIVIDADES DE FINANCIACION
A31: Aumento (Disminucion) Obligac. Financieras | C31: 0
A32: Aumento (Disminución) de Reservas | C32: =+'ESF=BALANCE'!L61-'ESF=BALANCE'!O61 -> -22284.601
A33: Aumento (Disminución) de Utilidades Ejercicios Anteriores | C33: =+'ESF=BALANCE'!L66-'ESF=BALANCE'!O63-'ESF=BALANCE'!O66 -> 11822.417
A36: TOTAL EFECTIVO PREVISTO POR LAS ACTIVIDADES DE FINANCIACION | C36: =SUM(C31:C35) -> -10462.184
A37: VARIACION DEL EFECTIVO | C37: =+C25+C29+C36 -> 491591.82
A38: EFECTIVO NETO AL INICIO DEL PERIODO
A39: Disponible | C39: =+'ESF=BALANCE'!G13+'ESF=BALANCE'!G14+'ESF=BALANCE'!G15 -> 314390.91
A40: Inversiones Temporales | C40: =+'ESF=BALANCE'!G16 -> 1952.4422
A41: SALDO FINAL DE EFECTIVO E INVERSIONES TEMPORALES | C41: =+C37+C39+C40 -> 807935.18 | F41: PRUEBA | G41: =+C41-C40-C39-C37 -> 0 | I41: =+'ESF=BALANCE'!D12-EFE!C41 -> -668484.05
A48: _____________________________ | B48: _________________________________________
A49: =+[1]DATOS!H12 -> Diego Botero Jaramillo | B49: LUZ AIDA HERNANDEZ GARCIA
A50: =+[1]DATOS!H13 -> C.C 71.787.709 | B50: 32.297.029
A51: Representante Legal | B51: Revisora Fiscal
...

Sheet ECP
A1: =+DATOS!H6 -> GRUPO DE LOLITA S.A.S
A2: =+DATOS!H7 -> NIT: 900.307.969-5
A3: =+DATOS!H8 -> A 30 de Junio de 2026 y 2025
A4: (Cifras expresadas en Miles de pesos colombianos)
C8: Capital | E8: Superavit de | G8: Reservas | I8: Utilidades/ Perdida | K8: Ajustes por Adopción | M8: Ajustes por corrección | O8: Ganancias Acumuladas | Q8: Perdidas Acumuladas | S8: Total
C9: social | E9: Capital | I9: Ejercicio | K9: NIIF | M9: NIIF | O9: Anteriores | Q9: Anteriores | S9: Patrimonio
A13: Saldo a Diciembre 31 de 2020 | C13: =+'ESF=BALANCE'!O55 -> 1737000 | E13: =+'ESF=BALANCE'!O57 -> 0 | G13: =+'ESF=BALANCE'!O60 -> 73934.518 | I13: =+'ESF=BALANCE'!O63 -> 32620.972 | K13: =+'ESF=BALANCE'!L68 -> 0 | M13: 0 | O13: =+'ESF=BALANCE'!O67 -> 339509.75 | Q13: 0 | S13: =+C13+E13+G13+I13+K13+O13 -> 2183065.2
A15: Aumento Capital | C15: 0 | E15: 0 | G15: 0 | I15: 0 | K15: 0 | M15: 0 | S15: =SUM(C15:Q15) -> 0
A17: Apropiacion Reserva Legal | C17: 0 | E17: 0 | G17: =+'ESF=BALANCE'!L60-'ESF=BALANCE'!O60 -> -22284.601 | I17: 0 | K17: 0 | M17: 0 | S17: =SUM(C17:Q17) -> -22284.601
A19: Participaciones Decretadas | C19: 0 | E19: 0 | G19: 0 | I19: 0 | K19: 0 | M19: 0 | O19: =-83536-0.5 -> -83536.5 | S19: =SUM(C19:Q19) -> -83536.5
A21: Para Capital de Trabajo | C21: 0 | E21: 0 | G21: 0 | I21: 0 | K21: 0 | M21: 0 | S21: =SUM(C21:Q21) -> 0
Q22: =SUM(B22:K22) -> 0
A23: Reclasificacion de Utilidades | C23: 0 | E23: 0 | G23: 0 | I23: =-'ESF=BALANCE'!O64 -> -32620.972 | K23: 0 | M23: 0 | O23: =-G17 -> 22284.601 | S23: =SUM(C23:Q23) -> -10336.371
A25: Utilidad/Perdida del Ejercicio | C25: 0 | E25: 0 | G25: 0 | I25: =+'ESF=BALANCE'!L63 -> 56988.014 | K25: 0 | M25: 0 | O25: =+I13 -> 32620.972 | S25: =SUM(C25:Q25) -> 89608.986
A27: Saldo a Diciembre 31 de 2021 | C27: =SUM(C13)+C21+C15 -> 1737000 | E27: =SUM(E13)+E21 -> 0 | G27: =+SUM(G13:G24) -> 51649.917 | I27: =SUM(I13)+I21+I23+I25 -> 56988.014 | K27: =SUM(K13)+K21+K23 -> 0 | O27: =+SUM(O13:O26) -> 310878.82 | Q27: =SUM(Q13)+Q21 -> 0 | S27: =SUM(S13)+S21+S23+S25+S19+S17+S15 -> 2156516.8
A37: ________________________________ | G37: ____________________________ | M37: ____________________________
A38: =+[1]DATOS!H12 -> Diego Botero Jaramillo | G38: LUZ AIDA HERNANDEZ GARCIA | M38: =+DATOS!H14 -> Leidy Yasmin Gomez Toro
A39: =+[1]DATOS!H13 -> C.C 71.787.709 | G39: CC: 32.297.029 | M39: ="TP: "&+DATOS!H15 -> TP: TP: 318364-T
A40: Representante Legal | G40: Revisora Fiscal | M40: Contador
G41: TP: 159803-T

Sheet INDICADORES
A1: =+DATOS!H6 -> GRUPO DE LOLITA S.A.S
A2: =+DATOS!H7 -> NIT: 900.307.969-5
A3: ANALISIS GERENCIAL
A4: =+DATOS!H8 -> A 30 de Junio de 2026 y 2025
A5: =+'E.R.I.ACUMULADO'!A6 -> (Cifras Expresadas en Miles de Pesos Colombianos)
A7: OTROS | B7: =+DATOS!H10 -> 2026-06 | C7: =+DATOS!H11 -> 2025-06
A8: EBITDA | B8: =+'E.R.I.ACUMULADO'!D109+DATOS!D121+DATOS!D122+DATOS!D140+DATOS!D141+DATOS!D150+DATOS!D179+DATOS!D180+DATOS!D155 -> 150787.69 | C8: =+'E.R.I.ACUMULADO'!G109+DATOS!G121+DATOS!G122+DATOS!G140+DATOS!G141+DATOS!G150+DATOS!G179+DATOS!G180+DATOS!G155 -> 87813.416
A9: CASH FLOW | B9: =+'E.R.I.ACUMULADO'!D109+DATOS!D179+DATOS!D140+DATOS!D121 -> 84457.904 | C9: =+'E.R.I.ACUMULADO'!G109+DATOS!G121+DATOS!G140+DATOS!G179 -> 38101.601
A10: GASTOS TOTALES (SIN PROVISION IMPUESTOS) | B10: =-(+'E.R.I.ACUMULADO'!D52+'E.R.I.ACUMULADO'!D30+'E.R.I.ACUMULADO'!D68+'E.R.I.ACUMULADO'!D80) -> 1082238.6 | C10: =-(+'E.R.I.ACUMULADO'!G30+'E.R.I.ACUMULADO'!G52+'E.R.I.ACUMULADO'!G68+'E.R.I.ACUMULADO'!G80) -> 1650195.1
A11: COSTO DE LA CARTERA | B11: =(+'ESF=BALANCE'!D22+'ESF=BALANCE'!D27+'ESF=BALANCE'!D28)*DATOS!H18 -> 62.161707 | C11: =(+'ESF=BALANCE'!G22+'ESF=BALANCE'!G27+'ESF=BALANCE'!G28)*DATOS!H18 -> 60.318756
A12: COSTO DEL INVENTARIO | B12: =+'ESF=BALANCE'!D30*DATOS!H18 -> 92.95325 | C12: =+'ESF=BALANCE'!G30*DATOS!H18 -> 818.49588
A13: PARTICIPACION DE GASTOS TOTALES EN LAS VENTAS | B13: =+B10/'E.R.I.ACUMULADO'!D13 -> 0.51130204 | C13: =+C10/'E.R.I.ACUMULADO'!G13 -> 0.5614946
A14: COSTO DE LA NOMINA EN LAS VENTAS | B14: =(+DATOS!D110+DATOS!D111+DATOS!D126+DATOS!D127+DATOS!D167+DATOS!D169+DATOS!D170+DATOS!D171+DATOS!D128+DATOS!D112)/'E.R.I.ACUMULADO'!D13 -> 0.26783046 | C14: =+(DATOS!G110+DATOS!G111+DATOS!G112+DATOS!G126+DATOS!G127+DATOS!G128+DATOS!G167+DATOS!G169+DATOS!G170+DATOS!G171)/'E.R.I.ACUMULADO'!G13 -> 0.23161572
A15: INDICADORES DE LIQUIDEZ | B15: =+B7 -> 2026-06 | C15: =+C7 -> 2025-06
A16: CAPITAL DE TRABAJO | B16: =+'ESF=BALANCE'!D38-'ESF=BALANCE'!L38 -> 677867.14 | C16: =+'ESF=BALANCE'!G38-'ESF=BALANCE'!O38 -> 252386.63
A17: RAZON CORRIENTE | B17: =+'ESF=BALANCE'!D38/'ESF=BALANCE'!L38 -> 2.8182163 | C17: =+'ESF=BALANCE'!G38/'ESF=BALANCE'!O38 -> 1.5651092
A19: INDICADORES DE ENDEUDAMIENTO | B19: =+B15 -> 2026-06 | C19: =+C15 -> 2025-06
A20: ENDEUDAMIENTO | B20: =+'ESF=BALANCE'!L51/'ESF=BALANCE'!D71 -> 0.49520014 | C20: =+'ESF=BALANCE'!O51/'ESF=BALANCE'!G71 -> 0.2651007
A21: ENDEUDAMIENTO A CORTO PLAZO | B21: =+'ESF=BALANCE'!L38/'ESF=BALANCE'!L51 -> 0.31984719 | C21: =+'ESF=BALANCE'!O38/'ESF=BALANCE'!O51 -> 0.57159264
A23: INDICADORES DE ACTIVIDAD | B23: =+B15 -> 2026-06 | C23: =+C15 -> 2025-06
A24: PROMEDIO CXC | B24: =+'ESF=BALANCE'!D22+'ESF=BALANCE'!D27+'ESF=BALANCE'!D28 -> 6216.1707 | C24: =+'ESF=BALANCE'!G22+'ESF=BALANCE'!G27+'ESF=BALANCE'!G28 -> 6031.8756
A25: ROTACIÒN C X C | B25: =+'E.R.I.ACUMULADO'!D13/INDICADORES!B24 -> 340.50427 | C25: =+'E.R.I.ACUMULADO'!G13/INDICADORES!C24 -> 487.23371
A26: ROTACIÒN DE CARTERA EN DIAS | B26: =(365/B25)/12*DATOS!H9 -> 0.53596979 | C26: =(365/C25)/12*DATOS!H9 -> 0.37456358
A28: PROMEDIO DE C X P | B28: =+'ESF=BALANCE'!L15 -> 134879.89 | C28: =+'ESF=BALANCE'!O15 -> 204376.72
A29: ROTACIÒN C X P | B29: =-'E.R.I.ACUMULADO'!D15/INDICADORES!B28 -> 7.0918788 | C29: =-'E.R.I.ACUMULADO'!G15/INDICADORES!C28 -> 6.0724381
A30: ROTACIÒN DE PROVEEDORES EN DIAS | B30: =(365/B29)/12*DATOS!H9 -> 25.73366 | C30: =(365/B29)/12*DATOS!H9 -> 25.73366
A32: INDICADORES DE RENTABILIDAD AÑO | B32: =+B23 -> 2026-06 | C32: =+C23 -> 2025-06
A33: MARGEN BRUTO | B33: =+'E.R.I.ACUMULADO'!E19 -> 0.54807848 | C33: =+'E.R.I.ACUMULADO'!H19 -> 0.57771582
A34: MARGEN OPERACIONAL | B34: =+'E.R.I.ACUMULADO'!E74 -> 0.07623705 | C34: =+'E.R.I.ACUMULADO'!H74 -> 0.046632394
A35: MARGEN NETO | B35: =+'E.R.I.ACUMULADO'!E109 -> 0.026923904 | C35: =+'E.R.I.ACUMULADO'!H109 -> 0.011099597
A36: RENDIMIENTO DEL PATRIMONIO | B36: =+'E.R.I.ACUMULADO'!D109/'ESF=BALANCE'!L69 -> 0.058415994 | C36: =+'E.R.I.ACUMULADO'!G109/'ESF=BALANCE'!O69 -> 0.015060265

Sheet BCE 2026
A1: OASIS URBANOS S.A.S - 901.630.218-1
A2: Balance de Prueba por NIT (Normal) Jun-30-2026
A3: Cuenta | B3: Equivalencia | C3: Nombre | D3: NIT | E3: Nombre NIT | F3: Saldo Anterior | G3: Débitos | H3: Créditos | I3: Nuevo Saldo | J3: NIVEL
A4: 1 | C4: ACTIVO | F4: 2.1383034e+09 | G4: 1.310329e+09 | H4: 1.2922827e+09 | I4: 2.1563497e+09 | J4: =+LEN(A4) -> 1
A5: 11 | C5: EFECTIVO Y EQUIV. AL EFECTIVO | F5: 1.3012075e+08 | G5: 1.0698603e+09 | H5: 1.0605299e+09 | I5: 1.3945113e+08 | J5: =+LEN(A5) -> 2
A6: 1105 | C6: CAJA | F6: 73332097 | G6: 5.5381128e+08 | H6: 561566319 | I6: 65577056 | J6: =+LEN(A6) -> 4
A7: 110505 | C7: CAJA GENERAL | F7: 73332097 | G7: 5.5381128e+08 | H7: 561566319 | I7: 65577056 | J7: =+LEN(A7) -> 6
A8: 11050501 | C8: CAJA CL VEGAS | F8: 15160301 | G8: 213949660 | H8: 220336561 | I8: 8773400 | J8: =+LEN(A8) -> 8
A9: 11050504 | C9: CAJA CL MEDELLIN | F9: 8125598.9 | G9: 200246488 | H9: 200309136 | I9: 8062950.9 | J9: =+LEN(A9) -> 8
A10: 11050508 | C10: CAJA CONSUMOS EMPLEADOS | F10: 0.01 | G10: 451781.02 | H10: 451781 | I10: 0.03 | J10: =+LEN(A10) -> 8
A11: 11050509 | C11: CAJA TORRE VEGAS | F11: 300000 | G11: 0 | H11: 0 | I11: 300000 | J11: =+LEN(A11) -> 8
A12: 11050510 | C12: CAJA CLINICA ONCOLOGICA | F12: 4325501 | G12: 77043390 | H12: 77624991 | I12: 3743900 | J12: =+LEN(A12) -> 8
A13: 11050511 | C13: CAJA SAN NICOLAS | F13: 399283.78 | G13: 61458100 | H13: 61458100 | I13: 399283.78 | J13: =+LEN(A13) -> 8
A14: 11050512 | C14: CAJA TRANSITORIA | F14: 45021412 | G14: 587730.69 | H14: 1311621 | I14: 44297522 | J14: =+LEN(A14) -> 8
A15: 11050520 | C15: CAJA RAPPI | F15: 0 | G15: 74129 | H15: 74129 | I15: 0 | J15: =+LEN(A15) -> 8
... A23: 11304001 | C23: DAVIVIENDA 0607039800123114 | F23: 419644.11 | G23: 3647.9 | H23: 0 | I23: 423292.01 | J23: =+LEN(A23) -> 8
A24: 11304001 | C24: DAVIVIENDA 0607039800123114 | D24: 800.182.281-5 | E24: FIDUCIARIA DAVIVIENDA S.A. | F24: 419644.11 | G24: 3647.9 | H24: 0 | I24: 423292.01 | J24: =+LEN(A24) -> 8
A25: 11304002 | C25: BANCOLOMBIA 0015-000304656 | F25: 15006747 | G25: 18110080 | H25: 0 | I25: 33116827 | J25: =+LEN(A25) -> 8
A26: 11304002 | C26: BANCOLOMBIA 0015-000304656 | D26: 800.180.687-2 | E26: FONDO DE INVERSION COLECTIVA A | F26: 3776748.7 | G26: 300920.44 | H26: 0 | I26: 4077669.2 | J26: =+LEN(A26) -> 8
A27: 11304002 | C27: BANCOLOMBIA 0015-000304656 | D27: 890.903.938-8 | E27: BANCOLOMBIA S.A | F27: 11229998 | G27: 17809160 | H27: 0 | I27: 29039158 | J27: =+LEN(A27) -> 8
A28: 13 | C28: CUENTAS POR COBRAR | F28: 7.7721896e+08 | G28: 56076425 | H28: 68835609 | I28: 7.6445977e+08 | J28: =+LEN(A28) -> 2
A29: 1305 | C29: CLIENTES | F29: 8674490.7 | G29: 15430490 | H29: 17888810 | I29: 6216170.7 | J29: =+LEN(A29) -> 4
A30: 130505 | C30: NACIONALES | F30: 8674490.7 | G30: 15430490 | H30: 17888810 | I30: 6216170.7 | J30: =+LEN(A30) -> 6
A31: 13050501 | C31: CLIENTES NACIONALES | F31: 8674490.7 | G31: 15340290 | H31: 17798610 | I31: 6216170.7 | J31: =+LEN(A31) -> 8
A32: 13050501 | C32: CLIENTES NACIONALES | D32: 800.219.876-9 | E32: SODEXO SERVICIOS DE BENEFICIOS | F32: 251500 | G32: 0 | H32: 0 | I32: 251500 | J32: =+LEN(A32) -> 8
A33: 13050501 | C33: CLIENTES NACIONALES | D33: 900.843.898-9 | E33: RAPPI S.A.S | F33: 8048912 | G33: 14283590 | H33: 16736810 | I33: 5595692 | J33: =+LEN(A33) -> 8
A34: 13050501 | C34: CLIENTES NACIONALES | D34: 901.461.076-5 | E34: ASESORIAS DF S.A.S | F34: 157100 | G34: 1056700 | H34: 1061800 | I34: 152000 | J34: =+LEN(A34) -> 8
A35: 13050501 | C35: CLIENTES NACIONALES | D35: 901.477.071-9 | E35: NUTRIENDO ALMAS S.A.S | F35: 216978.65 | G35: 0 | H35: 0 | I35: 216978.65 | J35: =+LEN(A35) -> 8
A36: 13050502 | C36: DESCUENTOS EMPLEADOS VB | F36: 0 | G36: 90200.02 | H36: 90200.02 | I36: 0 | J36: =+LEN(A36) -> 8
A37: 13050502 | C37: DESCUENTOS EMPLEADOS VB | D37: 1.036.640.645-8 | E37: FERNANDA ISABEL SANCHEZ MORALE | F37: 0 | G37: 90200.02 | H37: 90200.02 | I37: 0 | J37: =+LEN(A37) -> 8
A38: 1325 | C38: C X C A SOCIOS Y ACCIONISTAS | F38: 0 | G38: 0 | H38: 0 | I38: 0 | J38: =+LEN(A38) -> 4
A39: 132510 | C39: A ACCIONISTAS | F39: 0 | G39: 0 | H39: 0 | I39: 0 | J39: =+LEN(A39) -> 6
A40: 13251005 | C40: A ACCIONISTAS | F40: 0 | G40: 0 | H40: 0 | I40: 0 | J40: =+LEN(A40) -> 8
A41: 1330 | C41: ANTICIPOS Y AVANCES | F41: 6.234769e+08 | G41: 25428500 | H41: 0 | I41: 6.489054e+08 | J41: =+LEN(A41) -> 4
A42: 133005 | C42: A PROVEEDORES | F42: 0 | G42: 6241479 | H42: 0 | I42: 6241479 | J42: =+LEN(A42) -> 6
A43: 13300501 | C43: A PROVEEDORES | F43: 0 | G43: 6241479 | H43: 0 | I43: 6241479 | J43: =+LEN(A43) -> 8 | K43: QUITAR
A44: 13300501 | C44: A PROVEEDORES | D44: 43.869.549-8 | E44: ANA MARIA GIRALDO ARANGO | F44: 0 | G44: 1303343 | H44: 0 | I44: 1303343 | J44: =+LEN(A44) -> 8
A45: 13300501 | C45: A PROVEEDORES | D45: 71.776.741-8 | E45: ANDRES FELIPE MONTOYA VELEZ | F45: 0 | G45: 3072976 | H45: 0 | I45: 3072976 | J45: =+LEN(A45) -> 8
A46: 13300501 | C46: A PROVEEDORES | D46: 611.000.686-9 | E46: MARIO FERNANDO FILEVICH | F46: 0 | G46: 1089960 | H46: 0 | I46: 1089960 | J46: =+LEN(A46) -> 8
A47: 13300501 | C47: A PROVEEDORES | D47: 890.317.339-2 | E47: PALLOMARO S.A | F47: 0 | G47: 775200 | H47: 0 | I47: 775200 | J47: =+LEN(A47) -> 8
...

Sheet BCE 2025
A1: GRUPO DE LOLITA S.A.S - 900.307.969-5
A2: Balance de Prueba por NIT (Normal) Jun-30-2025
A3: Cuenta | B3: Equivalencia | C3: Nombre | D3: NIT | E3: Nombre NIT | F3: Saldo Anterior | G3: Débitos | H3: Créditos | I3: Nuevo Saldo | J3: NIVEL
A4: 1 | C4: ACTIVO | F4: 2.9175818e+09 | G4: 2.0084939e+09 | H4: 1.9786935e+09 | I4: 2.9473823e+09 | J4: =+LEN(A4) -> 1
A5: 11 | C5: EFECTIVO Y EQUIV. AL EFECTIVO | F5: -1.7410088e+08 | G5: 1.7310988e+09 | H5: 1.2406546e+09 | I5: 3.1634336e+08 | J5: =+LEN(A5) -> 2
A6: 1105 | C6: CAJA | F6: -2.7113116e+08 | G6: 1106516846 | H6: 621146791 | I6: 2.1423889e+08 | J6: =+LEN(A6) -> 4
A7: 110505 | C7: CAJA GENERAL | F7: -2.8290253e+08 | G7: 1106516846 | H7: 621146791 | I7: 2.0246753e+08 | J7: =+LEN(A7) -> 6
A8: 11050503 | C8: CAJA PUNTO CLAVE | F8: 0 | G8: 37353530 | H8: 37353530 | I8: 0 | J8: =+LEN(A8) -> 8
A9: 11050504 | C9: CAJA LIBERTAD | F9: 0 | G9: 72393220 | H9: 72393220 | I9: 0 | J9: =+LEN(A9) -> 8
A10: 11050505 | C10: CAJA GENERAL | F10: 1.5832484e-08 | G10: 180309302 | H10: 180309302 | I10: 1.5832484e-08 | J10: =+LEN(A10) -> 8
A11: 11050507 | C11: CAJA PLAZA FABRICATO | F11: 0 | G11: 49900830 | H11: 49900830 | I11: 0 | J11: =+LEN(A11) -> 8
A12: 11050508 | C12: CAJA MONTERREY | F12: 0 | G12: 68309480 | H12: 68309480 | I12: 0 | J12: =+LEN(A12) -> 8
A13: 11050509 | C13: CAJA CLINICA PRADO | F13: 0 | G13: 95381350 | H13: 95381350 | I13: 0 | J13: =+LEN(A13) -> 8
A14: 11050511 | C14: CAJA TORRE MEDICA | F14: 0 | G14: 51646160 | H14: 51646160 | I14: 0 | J14: =+LEN(A14) -> 8
A15: 11050512 | C15: CAJA TRANSITORIA | F15: -2.8320253e+08 | G15: 489289834 | H15: 3919779 | I15: 2.0216753e+08 | J15: =+LEN(A15) -> 8
... A46: 13050501 | C46: CLIENTES NACIONALES | F46: 4.9554714e+08 | G46: 7931791.9 | H46: 4.9760406e+08 | I46: 5874875.6 | J46: =+LEN(A46) -> 8
A47: 13050501 | C47: CLIENTES NACIONALES | D47: 800.142.245-9 | E47: CIUDADELA COMERCIAL UNICENTRO | F47: 989000 | G47: 0 | H47: 989000 | I47: 0 | J47: =+LEN(A47) -> 8
A48: 13050501 | C48: CLIENTES NACIONALES | D48: 890.901.389-5 | E48: UNIVERSIDAD EAFIT | F48: 137100 | G48: 62100 | H48: 137100 | I48: 62100 | J48: =+LEN(A48) -> 8
A49: 13050501 | C49: CLIENTES NACIONALES | D49: 900.206.485-9 | E49: DE LOLITA RESTO CAFE S.A.S | F49: 3407521.4 | G49: 1634511.9 | H49: 1368673.5 | I49: 3673359.8 | J49: =+LEN(A49) -> 8
A50: 13050501 | C50: CLIENTES NACIONALES | D50: 900.843.898-9 | E50: RAPPI S.A.S | F50: 768375.75 | G50: 5859280 | H50: 4714540 | I50: 1913115.8 | J50: =+LEN(A50) -> 8
A51: 13050501 | C51: CLIENTES NACIONALES | D51: 900.956.336-7 | E51: SOY TU PEDIATRA INSTITUCION PR | F51: 186400 | G51: 39900 | H51: 0 | I51: 226300 | J51: =+LEN(A51) -> 8
A52: 13050501 | C52: CLIENTES NACIONALES | D52: 901.038.452-9 | E52: CONJUNTO INMOBILIARIO CALLE 50 | F52: 496700 | G52: 336000 | H52: 832700 | I52: 0 | J52: =+LEN(A52) -> 8
A53: 13050501 | C53: CLIENTES NACIONALES | D53: 901.448.316-4 | E53: SOMOS UNO RESTO CAFE SAS | F53: 138018.4 | G53: 0 | H53: 138018.4 | I53: 0 | J53: =+LEN(A53) -> 8
A54: 13050501 | C54: CLIENTES NACIONALES | D54: 901.477.071-9 | E54: NUTRIENDO ALMAS S.A.S | F54: 171194.75 | G54: 0 | H54: 171194.75 | I54: 0 | J54: =+LEN(A54) -> 8
A55: 13050501 | C55: CLIENTES NACIONALES | D55: 901.549.804-0 | E55: INSPIRAMOS EL MAÑANA S.A.S | F55: 131848502 | G55: 0 | H55: 131848502 | I55: 0 | J55: =+LEN(A55) -> 8
A56: 13050501 | C56: CLIENTES NACIONALES | D56: 901.550.284-2 | E56: CONVOCAMOS SERES DE AMOR S.A.S | F56: 53463134 | G56: 0 | H56: 53463134 | I56: 0 | J56: =+LEN(A56) -> 8
A57: 13050501 | C57: CLIENTES NACIONALES | D57: 901.630.218-1 | E57: OASIS URBANOS S.A.S. | F57: 303941198 | G57: 0 | H57: 303941198 | I57: 0 | J57: =+LEN(A57) -> 8
A58: 13050502 | C58: DESCUENTOS EMPLEADOS VB | F58: 243000.02 | G58: 157000 | H58: 243000 | I58: 157000.02 | J58: =+LEN(A58) -> 8
A59: 13050502 | C59: DESCUENTOS EMPLEADOS VB | D59: 5.740.264-0 | E59: CASTILLO YEPEZ YAMILETH COROMO | F59: 36000 | G59: 0 | H59: 36000 | I59: 0 | J59: =+LEN(A59) -> 8
A60: 13050502 | C60: DESCUENTOS EMPLEADOS VB | D60: 15.518.713-2 | E60: DAVID FERNANDO MEJIA ECHEVERRI | F60: 31000 | G60: 28000 | H60: 31000 | I60: 28000 | J60: =+LEN(A60) -> 8
A61: 13050502 | C61: DESCUENTOS EMPLEADOS VB | D61: 21.853.973-8 | E61: VERONICA JOHANA MORENO LOPERA | F61: 52000 | G61: 45000 | H61: 52000 | I61: 45000 | J61: =+LEN(A61) -> 8
A62: 13050502 | C62: DESCUENTOS EMPLEADOS VB | D62: 43.686.015-0 | E62: MARIA EUGENIA VASQUEZ PALACIO | F62: 30000 | G62: 0 | H62: 30000 | I62: 0 | J62: =+LEN(A62) -> 8
A63: 13050502 | C63: DESCUENTOS EMPLEADOS VB | D63: 860.002.134-8 | E63: ABBOTT LABORATORIES DE COLOMBI | F63: 39000.02 | G63: 0 | H63: 0 | I63: 39000.02 | J63: =+LEN(A63) -> 8
A64: 13050502 | C64: DESCUENTOS EMPLEADOS VB | D64: 1.036.644.200-2 | E64: MARIA FERNANDA ARAQUE RAMIREZ | F64: 0 | G64: 84000 | H64: 39000 | I64: 45000 | J64: =+LEN(A64) -> 8
A65: 13050502 | C65: DESCUENTOS EMPLEADOS VB | D65: 1.070.591.915-4 | E65: EDER JOHAN BAUTISTA | F65: 18000 | G65: 0 | H65: 18000 | I65: 0 | J65: =+LEN(A65) -> 8
A66: 13050502 | C66: DESCUENTOS EMPLEADOS VB | D66: 1.151.477.226-4 | E66: SEVERICHE BLANCO INGRID PAOLA_x000D_ | F66: 37000 | G66: 0 | H66: 37000 | I66: 0 | J66: =+LEN(A66) -> 8
A67: 1325 | C67: C X C A SOCIOS Y ACCIONISTAS | F67: 0 | G67: 0 | H67: 0 | I67: 0 | J67: =+LEN(A67) -> 4
A68: 132510 | C68: A ACCIONISTAS | F68: 0 | G68: 0 | H68: 0 | I68: 0 | J68: =+LEN(A68) -> 6
A69: 13251005 | C69: A ACCIONISTAS | F69: 0 | G69: 0 | H69: 0 | I69: 0 | J69: =+LEN(A69) -> 8
A70: 1330 | C70: ANTICIPOS Y AVANCES | F70: 1.6593646e+08 | G70: 27380603 | H70: 8670103 | I70: 1.8464696e+08 | J70: =+LEN(A70) -> 4
...

Sheet PROVISION RENTA
A1: CALCULO DE IMPUESTO CORRIENTE AÑO 2020
A2: =+'E.R.I.ACUMULADO'!A2 -> GRUPO DE LOLITA S.A.S
A3: ="CALCULO DE IMPUESTO CORRIENTE AÑO " &DATOS!C3 -> CALCULO DE IMPUESTO CORRIENTE AÑO 2025
A5: (Cifras Expresadas en Miles de Pesos Colombianos) | F5: DILIGENCIAR LOS VALORES EN GRIS
A8: UTILIDAD CONTABLE ACUMULADA | B8: =+'E.R.I.ACUMULADO'!D89 -> 91324.014 | C8: Arrastrar del acumulado a la fecha
A10: Gastos No Deducibles | B10: 0 | D10: A
A11: Intereses Por Mora Fiscal | B11: 0 | D11: C
A12: Costos y Gastos de Ejercicios Ant | B12: 0 | D12: D
A13: Impuestos Asumidos | B13: 0 | D13: E
A14: GMF 50% | B14: 9949.5 | D14: F
A15: Multas y Sanciones | B15: 0
A16: Donaciones | B16: 0
A17: UTILIDAD FISCAL | B17: =SUM(B8:B16) -> 101273.51
A20: calculo de Anticipo
A21: Impuesto renta 2023 | B21: 154335
A22: Impuesto de Renta Aprox | B22: =IF((B17*0.35)>=0,(B17*0.35),B26) -> 35445.73
A23: Promedio o Menor impùesto | B23: =+IF(((B21+B22)/2)>+B22,B22,(B21+B22)/2) -> 35445.73
A25: Renta Presuntiva | B25: =+(L25*0.5%/1000) -> 6868.505 | E25: PATRIMONIO LIQUIDO AÑO ANTERIOR | H25: 1373701000 | I25: ACTIVOS NO PROD | K25: 0 | L25: =+H25-K25 -> 1373701000
A26: Impuesto de Renta Presuntiva | B26: =+B25*0.35 -> 2403.9767
A28: Anticipo 75%-50%-25% | B28: =+B23*0.75 -> 26584.297
A29: Retenciones Practicadas | B29: 70105
A30: Autorretencion Especial | B30: 76466 | D30: G
A31: valor de Anticipo | B31: =+IF((B28-B29-B30)>0,(B28-B29-B30),0) -> 0
A33: Impuesto de Renta | B33: =+IF(B22>B26,B22,B26) -> 35445.73 | D33: PROVISIONAR
A34: Saldo a Favor Renta año anterior | B34: 904
A35: Anticipo de Renta año anterior | B35: 0
A36: Saldo a Favor/ Pagar Aprox Renta | B36: =+B33-B34-B35-B29-B30+B31 -> -112029.27 | C36: =+IF(B36>=0,"A PAGAR","A FAVOR") -> A FAVOR
A38: REQUIERE PLANEACIÓN | C38: =+IF(B36>0,"SI","NO") -> NO

Sheet NOTAS
B1: =+DATOS!$H$10 -> 2026-06 | C1: =+DATOS!$H$11 -> 2025-06 | F1: =+DATOS!$H$10 -> 2026-06 | G1: =+DATOS!$H$11 -> 2025-06 | J1: =+DATOS!$H$10 -> 2026-06 | K1: =+DATOS!$H$11 -> 2025-06
A2: Efectivo y Equivalentes de Efectivo | B2: =SUM(B3:B6) -> 139451.13 | C2: =SUM(C3:C6) -> 316343.36 | E2: Activos por Impuesto | F2: =+F3 -> 137480.76 | G2: =+G3 -> 67881.501 | I2: Cuentas Por Cobrar | J2: =SUM(J3:J6) -> 764459.77 | K2: =SUM(K3:K6) -> 232927.86
A3: Caja | B3: =+'ESF=BALANCE'!D13 -> 65577.056 | C3: =+'ESF=BALANCE'!G13 -> 214238.89 | E3: Anticipo de Impuestos | F3: =+'ESF=BALANCE'!D19 -> 137480.76 | G3: =+'ESF=BALANCE'!G19 -> 67881.501 | I3: Clientes | J3: =+'ESF=BALANCE'!D22 -> 6216.1707 | K3: =+'ESF=BALANCE'!G22 -> 6031.8756
A4: Bancos | B4: =+'ESF=BALANCE'!D14 -> 40333.952 | C4: =+'ESF=BALANCE'!G14 -> 81215.599 | I4: Anticipos y avances | J4: =+'ESF=BALANCE'!D23 -> 648905.4 | K4: =+'ESF=BALANCE'!G23 -> 184646.96
A5: Cuentas de ahorros | B5: =+'ESF=BALANCE'!D15 -> 0 | C5: =+'ESF=BALANCE'!G15 -> 18936.424 | I5: A empleados | J5: =+'ESF=BALANCE'!D24 -> 852.794 | K5: =+'ESF=BALANCE'!G24 -> 1997.585
A6: Inversiones a la vista | B6: =+'ESF=BALANCE'!D16 -> 33540.119 | C6: =+'ESF=BALANCE'!G16 -> 1952.4422 | I6: Deudores varios | J6: =+'ESF=BALANCE'!D25 -> 108485.41 | K6: =+'ESF=BALANCE'!G25 -> 40251.44
J9: =+DATOS!$H$10 -> 2026-06 | K9: =+DATOS!$H$11 -> 2025-06
F10: =+DATOS!$H$10 -> 2026-06 | G10: =+DATOS!$H$11 -> 2025-06 | I10: Intangibles | J10: =+J11 -> 764766.8 | K10: =+K11 -> 220000
B11: =+DATOS!$H$10 -> 2026-06 | C11: =+DATOS!$H$11 -> 2025-06 | E11: Propiedad Planta y Equipo | F11: =SUM(F12:F18) -> 538379.65 | G11: =SUM(G12:G18) -> 2028379.9 | I11: Concesiones y Franquicias | J11: =+'ESF=BALANCE'!D60 -> 764766.8 | K11: =+'ESF=BALANCE'!G60 -> 220000
A12: Inventarios | B12: =SUM(B13:B13) -> 9295.325 | C12: =+C13 -> 81849.588 | E12: Mejoras a propiedades Ajenas | F12: =+'ESF=BALANCE'!D51 -> 0 | G12: =+'ESF=BALANCE'!G51 -> 355856.13
A13: Mercancia no fabricada por la empresa | B13: =+'ESF=BALANCE'!D30 -> 9295.325 | C13: =+'ESF=BALANCE'!G34 -> 81849.588 | E13: Construcciones y edificaciones | F13: =+'ESF=BALANCE'!D52 -> 0 | G13: =+'ESF=BALANCE'!G52 -> 1286225.2
E14: Maquinaria y equipo | F14: =+'ESF=BALANCE'!D53 -> 534086.15 | G14: =+'ESF=BALANCE'!G53 -> 455026.46
E15: Equipo de oficina | F15: =+'ESF=BALANCE'!D54 -> 0 | G15: =+'ESF=BALANCE'!G54 -> 210990.46
E16: Equipo de computo | F16: =+'ESF=BALANCE'!D55 -> 4293.503 | G16: =+'ESF=BALANCE'!G55 -> 42702.049
E17: Flota y equipo de transporte | F17: =+'ESF=BALANCE'!D56 -> 0 | G17: =+'ESF=BALANCE'!G56 -> 0
E18: Depreciacion acumulada | F18: =+'ESF=BALANCE'!D57 -> 0 | G18: =+'ESF=BALANCE'!G57 -> -322420.39
J19: =+DATOS!$H$10 -> 2026-06 | K19: =+DATOS!$H$11 -> 2025-06
B20: =+DATOS!$H$10 -> 2026-06 | C20: =+DATOS!$H$11 -> 2025-06 | I20: Pasivo Por Impuestos | J20: =SUM(J21:J23) -> 177433.75 | K20: =SUM(K21:K23) -> 126229.07
A21: Activo por impuesto | B21: =+B22 -> 0 | C21: =+C22 -> 0 | F21: =+DATOS!$H$10 -> 2026-06 | G21: =+DATOS!$H$11 -> 2025-06 | I21: Impuesto sobre las ventas | J21: =+'ESF=BALANCE'!L20 -> 133798.75 | K21: =+'ESF=BALANCE'!O20 -> 73042.873
A22: Impuesto diferido | B22: =+DATOS!C42 -> 0 | C22: =+'ESF=BALANCE'!G66 -> 0 | E22: Cuentas Por Pagar | F22: =SUM(F23:F24) -> 134879.89 | G22: =SUM(G23:G24) -> 204376.72 | I22: Retenciòn en la fuente | J22: =+'ESF=BALANCE'!L21 -> 9299 | K22: =+'ESF=BALANCE'!O21 -> 26515
E23: Proveedores | F23: =+'ESF=BALANCE'!L16 -> 113653.71 | G23: =+'ESF=BALANCE'!O16 -> 198797.21 | I23: Impuesto a las ganancias | J23: =+'ESF=BALANCE'!L23 -> 34336 | K23: =+'ESF=BALANCE'!O23 -> 26671.196
E24: Costos y gastos por pagar | F24: =+'ESF=BALANCE'!L17 -> 21226.182 | G24: =+'ESF=BALANCE'!O17 -> 5579.505
J26: =+DATOS!$H$10 -> 2026-06 | K26: =+DATOS!$H$11 -> 2025-06 | M26: CUENTA | N26: SALDO ANTERIOR | O26: AJUSTES | Q26: SALDO ACTUAL
B27: =+DATOS!$H$10 -> 2026-06 | C27: =+DATOS!$H$11 -> 2025-06 | I27: Pasivo Por Impuestos | J27: =+J28 -> 0 | K27: =+K28 -> 4118.228 | O27: DEBITO | P27: CREDITO
