Workbook
Name _PT1: '[1]datos decreto y Resol'!#REF!
Name aaaaaaaaaaa: #REF!
Name ACTIVOS3333: #REF!
Name Adquisición: [2]Listas!$B$9:$B$14
Name Adquisición: [3]Listas!$B$9:$B$14
Name Avaluo: [4]Listas!$B$19:$B$20
Name Avaluo: [5]Listas!$B$19:$B$20
Name AVALÚO: [6]Listas!$B$19:$B$20
Name AVALÚO: [7]Listas!$B$19:$B$20
Name BALASAS2: #REF!
Name BALASAS3: #REF!
Name ClasificaciónNIIF: [8]Listas!$B$13:$B$17
Name cuota3..: '[1]datos decreto y Resol'!#REF!
Name D: #REF!
Name DCA: #REF!
Name DCAC: #REF!
Name DCAC: #REF!
Name DCAC: #REF!
Name DCAC: #REF!
Name DCAC: #REF!
Name DCAD: #REF!
Name DCGD: #REF!
Name DCGD: [9]Listas!#REF!
Name DD: #REF!
Name DD: #REF!
Name DD: #REF!
Name DD: #REF!
Name DD: #REF!
Name DDD: #REF!
Name DDD: #REF!
Name DDD: #REF!
Name DDD: #REF!
Name DDD: #REF!
Name DDDA: #REF!
Name DDDA: #REF!
Name DDDA: #REF!
Name DDDA: #REF!
Name DDDA: #REF!
Name DDDD: #REF!
Name DDDD: #REF!
Name DDDD: #REF!
Name DDDD: #REF!
Name DDDD: #REF!
Name DDDD1: #REF!
Name Declaraciones: #REF!
Name Declaraciones: #REF!
Name Declaraciones: #REF!
Name Declaraciones: #REF!
Name Declaraciones: #REF!
Name ded: #REF!
Name ded: #REF!
Name ded: #REF!
Name ded: #REF!
Name ded: #REF!
Name Diarios: #REF!
Name Diarios: #REF!
Name Diarios: #REF!
Name Diarios: #REF!
Name Diarios: #REF!
Name e: #REF!

Sheet DATOS
A1: TODOS LOS VALORES SE DIGITAN POSITIVOS EXEPTO DEPRECIACIONES
A3: PUC SOLO UNA GUIA NO ES IGUAL EN TODOS | C3: 2026 | E3: 2025
A4: 1 | B4: ACTIVO | C4: =C5+C10+C17+C20+C27+C29+C31 -> 3462278 | E4: =E5+E10+E17+E20+E27+E29+E31 -> 2947383
A5: 11 | B5: EFECTIVO Y EQUIV. AL EFECTIVO | C5: =SUM(C6:C9) -> 576780 | E5: =+SUM(E6:E9) -> 316343
A6: 1105 | B6: CAJA | C6: =+SUMIF('6.BP2026'!A:A,DATOS!A6,'6.BP2026'!I:I) -> 462620 | E6: =+SUMIF('7.BP2025'!A:A,DATOS!A6,'7.BP2025'!I:I) -> 214239 | G6: EMPRESA | H6: GRUPO DE LOLITA SAS
A7: 1110 | B7: BANCOS | C7: =+SUMIF('6.BP2026'!A:A,DATOS!A7,'6.BP2026'!I:I) -> 34966 | E7: =+SUMIF('7.BP2025'!A:A,DATOS!A7,'7.BP2025'!I:I) -> 81216 | G7: NIT | H7: NIT: 900.307.969-5
A8: 1120 | B8: CUENTAS DE AHORROS | C8: =+SUMIF('6.BP2026'!A:A,DATOS!A8,'6.BP2026'!I:I) -> 37524 | E8: =+SUMIF('7.BP2025'!A:A,DATOS!A8,'7.BP2025'!I:I) -> 18936 | G8: FECHA DE CORTE | H8: A 30 DE JUNIO DE 2026 Y 2025
A9: 1130 | B9: EQUIVALENTES AL EFECTIVO | C9: =+SUMIF('6.BP2026'!A:A,DATOS!A9,'6.BP2026'!I:I) -> 41670 | E9: =+SUMIF('7.BP2025'!A:A,DATOS!A9,'7.BP2025'!I:I) -> 1952 | G9: MES | H9: 6
A10: 13 | B10: CUENTAS POR COBRAR | C10: =SUM(C11:C16) -> 437305 | E10: =SUM(E11:E16) -> 232928 | G10: FECHA E.F | H10: 2026-06
A11: 1305 | B11: CLIENTES | C11: =+SUMIF('6.BP2026'!A:A,DATOS!A11,'6.BP2026'!I:I) -> 21421 | E11: =+SUMIF('7.BP2025'!A:A,DATOS!A11,'7.BP2025'!I:I) -> 6032 | G11: FECHA E.F COMP | H11: 2025-06
A12: 1325 | B12: CXC SOCIOS Y ACCIONISTAS | C12: =+SUMIF('6.BP2026'!A:A,DATOS!A12,'6.BP2026'!I:I) -> 0 | E12: =+SUMIF('7.BP2025'!A:A,DATOS!A12,'7.BP2025'!I:I) -> 0 | G12: Representante Legal | H12: MARIO FERNANDO FILEVICH
A13: 1330 | B13: ANTICIPOS Y AVANCES | C13: =+SUMIF('6.BP2026'!A:A,DATOS!A13,'6.BP2026'!I:I) -> 327590 | E13: =+SUMIF('7.BP2025'!A:A,DATOS!A13,'7.BP2025'!I:I) -> 184647 | G13: Cedula Rep Legal | H13: C.E 274.113
A14: 1355 | B14: ANTICIPO IMPUESTOS Y CONTRIB | C14: =+SUMIF('6.BP2026'!A:A,DATOS!A14,'6.BP2026'!I:I) -> 0 | E14: =+SUMIF('7.BP2025'!A:A,DATOS!A14,'7.BP2025'!I:I) -> 0
A15: 1365 | B15: PRESTAMOS A EMPLEADOS | C15: =+SUMIF('6.BP2026'!A:A,DATOS!A15,'6.BP2026'!I:I) -> 363 | E15: =+SUMIF('7.BP2025'!A:A,DATOS!A15,'7.BP2025'!I:I) -> 1998 | G15: Contador | H15: LUZ AIDA HERNANDEZ GARCIA
A16: 1380 | B16: DEUDORES VARIOS | C16: =+SUMIF('6.BP2026'!A:A,DATOS!A16,'6.BP2026'!I:I) -> 87931 | E16: =+SUMIF('7.BP2025'!A:A,DATOS!A16,'7.BP2025'!I:I) -> 40251 | G16: T.P: | H16: 159803-T
A17: 14 | B17: INVENTARIOS | C17: =SUM(C18:C19) -> 78249 | E17: =SUM(E18:E19) -> 81850 | G17: Revisor Fiscal
A18: 1435 | B18: MERCANCIAS NO FABRICADAS POR L | C18: =+SUMIF('6.BP2026'!A:A,DATOS!A18,'6.BP2026'!I:I) -> 78249 | E18: =+SUMIF('7.BP2025'!A:A,DATOS!A18,'7.BP2025'!I:I) -> 81850 | G18: T.P:
A19: 1436 | B19: OTROS INVENTARIOS | C19: =+SUMIF('6.BP2026'!A:A,DATOS!A19,'6.BP2026'!I:I) -> 0 | E19: =+SUMIF('7.BP2025'!A:A,DATOS!A19,'7.BP2025'!I:I) -> 0 | G19: TASA DE MERCADO | H19: 0.01
A20: 15 | B20: PROPIEDAD PLANTA Y EQUIPO | C20: =SUM(C21:C26) -> 1983687 | E20: =SUM(E21:E26) -> 2028380
A21: 1510 | B21: MEJORAS A PROPIEDADES AJENAS | C21: =+SUMIF('6.BP2026'!A:A,DATOS!A21,'6.BP2026'!I:I) -> 339255 | E21: =+SUMIF('7.BP2025'!A:A,DATOS!A21,'7.BP2025'!I:I) -> 355856
A22: 1516 | B22: CONSTRUCCIONES Y ED | C22: =+SUMIF('6.BP2026'!A:A,DATOS!A22,'6.BP2026'!I:I)-(SUMIF('6.BP2026'!A:A,151692,'6.BP2026'!I:I)/2) -> 1286225.5 | E22: =+SUMIF('7.BP2025'!A:A,DATOS!A22,'7.BP2025'!I:I)-(SUMIF('7.BP2025'!A:A,151692,'7.BP2025'!I:I)/2) -> 1286226
A23: 1520 | B23: MAQUINARIA Y EQUIPO | C23: =+SUMIF('6.BP2026'!A:A,DATOS!A23,'6.BP2026'!I:I)-(SUMIF('6.BP2026'!A:A,152092,'6.BP2026'!I:I)/2) -> 463303 | E23: =+SUMIF('7.BP2025'!A:A,DATOS!A23,'7.BP2025'!I:I)-(SUMIF('7.BP2025'!A:A,152092,'7.BP2025'!I:I)/2) -> 455027
A24: 1524 | B24: EQUIPO DE OFICINA | C24: =+SUMIF('6.BP2026'!A:A,DATOS!A24,'6.BP2026'!I:I)-(SUMIF('6.BP2026'!A:A,152492,'6.BP2026'!I:I)/2) -> 210990 | E24: =+SUMIF('7.BP2025'!A:A,DATOS!A24,'7.BP2025'!I:I)-(SUMIF('7.BP2025'!A:A,152492,'7.BP2025'!I:I)/2) -> 210990
A25: 1528 | B25: EQUIPOS DE PROCESAMIENTO DE DA | C25: =+SUMIF('6.BP2026'!A:A,DATOS!A25,'6.BP2026'!I:I)-(SUMIF('6.BP2026'!A:A,152892,'6.BP2026'!I:I)/2) -> 42702 | E25: =+SUMIF('7.BP2025'!A:A,DATOS!A25,'7.BP2025'!I:I)-(SUMIF('7.BP2025'!A:A,152892,'7.BP2025'!I:I)/2) -> 42702
A26: 1592 | B26: DEPRECIACION ACUMULADA | C26: =+SUMIF('6.BP2026'!A:A,DATOS!A26,'6.BP2026'!I:I)+(SUMIF('6.BP2026'!A:A,151692,'6.BP2026'!I:I)/2)+(SUMIF('6.BP2026'!A:A,152092,'6.BP2026'!I:I)/2)+(SUMIF('6.BP2026'!A:A,152492,'6.BP2026'!I:I)/2)+(SUMIF('6.BP2026'!A:A,152892,'6.BP2026'!I:I)/2) -> -358788.5 | E26: =+SUMIF('7.BP2025'!A:A,DATOS!A26,'7.BP2025'!I:I)+(SUMIF('7.BP2025'!A:A,151092,'7.BP2025'!I:I)/2)+(SUMIF('7.BP2025'!A:A,151692,'7.BP2025'!I:I)/2)+(SUMIF('7.BP2025'!A:A,152092,'7.BP2025'!I:I)/2)+(SUMIF('7.BP2025'!A:A,152492,'7.BP2025'!I:I)/2)+(SUMIF('7.BP2025'!A:A,152892,'7.BP2025'!I:I)/2) -> -322421
A27: 16 | B27: INTANGIBLES | C27: =SUM(C28:C28) -> 184351 | E27: =SUM(E28:E28) -> 220000
A28: 16 | B28: CONCESIONES Y FRANQUICIAS | C28: =+SUMIF('6.BP2026'!A:A,DATOS!A28,'6.BP2026'!I:I) -> 184351 | E28: =+SUMIF('7.BP2025'!A:A,DATOS!A28,'7.BP2025'!I:I) -> 220000
A29: 17 | B29: OTROS ACTIVOS | C29: =SUM(C30:C30) -> 7521 | E29: =SUM(E30:E30) -> 0
A30: 17 | B30: GASTOS PAGADOS POR ANTICIPADO | C30: =+SUMIF('6.BP2026'!A:A,DATOS!A30,'6.BP2026'!I:I) -> 7521 | E30: =+SUMIF('7.BP2025'!A:A,DATOS!A30,'7.BP2025'!I:I) -> 0
A31: 19 | B31: ACTIVOS POR IMPUESTOS | C31: =+C32 -> 194385 | E31: =+E32 -> 67882
A32: 1955 | B32: ANTICIPO DE IMPUESTO Y SALDOS A FAVOR | C32: =+SUMIF('6.BP2026'!A:A,DATOS!A32,'6.BP2026'!I:I) -> 194385 | E32: =+SUMIF('7.BP2025'!A:A,DATOS!A32,'7.BP2025'!I:I) -> 67882
A33: 2 | B33: PASIVO | C33: =C34+C38+C40+C46+C56+C67+C69 -> 1131133 | E33: =+E34+E38+E40+E46+E56+E67+E69 -> 781353
A34: 21 | B34: OBLIGACIONES FINANCIERAS | C34: =SUM(C35:C37) -> 330754 | E34: =SUM(E35:E37) -> 330620
A35: 2105 | B35: OBLIGACIONES FINANCIERAS | C35: =-SUMIF('6.BP2026'!A:A,DATOS!A35,'6.BP2026'!I:I) -> 269433 | E35: =-SUMIF('7.BP2025'!A:A,DATOS!A35,'7.BP2025'!I:I) -> 302914
A36: 2120 | B36: COMPAÑIAS DE FINANCIAMIENTO CO | C36: =-SUMIF('6.BP2026'!A:A,DATOS!A36,'6.BP2026'!I:I) -> 3420 | E36: =-SUMIF('7.BP2025'!A:A,DATOS!A36,'7.BP2025'!I:I) -> 3420
A37: 2195 | B37: OTRAS OBLIGACIONES | C37: =-SUMIF('6.BP2026'!A:A,DATOS!A37,'6.BP2026'!I:I) -> 57901 | E37: =-SUMIF('7.BP2025'!A:A,DATOS!A37,'7.BP2025'!I:I) -> 24286
A38: 22 | B38: PROVEEDORES | C38: =SUM(C39:C39) -> 497599 | E38: =SUM(E39:E39) -> 198797
A39: 2205 | B39: NACIONALES | C39: =-SUMIF('6.BP2026'!A:A,DATOS!A39,'6.BP2026'!I:I) -> 497599 | E39: =-SUMIF('7.BP2025'!A:A,DATOS!A39,'7.BP2025'!I:I) -> 198797
A40: 23 | B40: CUENTAS POR PAGAR | C40: =SUM(C41:C45) -> 29514 | E40: =SUM(E41:E45) -> 5579
A41: 2335 | B41: COSTOS Y GASTOS POR PAGAR | C41: =-SUMIF('6.BP2026'!A:A,DATOS!A41,'6.BP2026'!I:I) -> 0 | E41: =-SUMIF('7.BP2025'!A:A,DATOS!A41,'7.BP2025'!I:I) -> 0
...

Sheet RESULTADOS GRUPO
B1: =+B3 -> 2 | C1: =+C3 -> 3 | D1: =+D3 -> 2 | E1: =+E3 -> 5 | F1: =+F3 -> 12
A2: MES ENERO | B2: GRUPO DL | C2: INSPIRAMOS | D2: CONVOCAMOS | E2: OASIS | F2: TOTAL
A3: CANTIDAD OASIS | B3: 2 | C3: 3 | D3: 2 | E3: 5 | F3: =SUM(B3:E3) -> 12
A4: VENTAS ENERO | F4: =SUM(B4:E4) -> 0
A5: UTILIDAD ANTES DE IMPUESTO | F5: =SUM(B5:E5) -> 0
A6: UTILIDAD DESPUES DE IMPUESTO | F6: =SUM(B6:E6) -> 0
A7: VR FT SOCIOS | F7: =SUM(B7:E7) -> 0
A8: UTILIDAD REEXPRESADA ANTES DE IMP | B8: =+B6+B7 -> 0 | C8: =+C6+C7-5 -> -5 | D8: =+D6+D7 -> 0 | E8: =+E6+E7 -> 0 | F8: =SUM(B8:E8) -> -5 | H8: =+F4*5% -> 0 | I8: =+H8/F4 -> #DIV/0!
B9: =+B8/B4 -> #DIV/0! | C9: =+C8/C4 -> #DIV/0! | D9: =+D8/D4 -> #DIV/0! | E9: =+E8/E4 -> #DIV/0! | F9: =+F8/F4 -> #DIV/0!
A11: ACUMULADO | B11: GRUPO DL | C11: INSPIRAMOS | D11: CONVOCAMOS | E11: OASIS | F11: TOTAL
A12: TOTAL VENTAS ACUMULADAS | H12: =+B12-'2.E.R.I. MES-ACUMULADO'!CM13 -> -3042065.5 | I12: =+B13-'2.E.R.I. MES-ACUMULADO'!CM152 -> -56427 | J12: =+B15-'2.E.R.I. MES-ACUMULADO'!CM158 -> -39744
A13: UTILIDAD ANTES DE IMPUESTO | G13: =+F13/F12 -> #DIV/0! | H13: =+B13-'2.E.R.I. MES-ACUMULADO'!CM152 -> -56427
G14: 8% PARA TODAS LAS CIAS
A15: UTILIDAD DESPUES DE IMPUESTO | H15: =+B15-'2.E.R.I. MES-ACUMULADO'!CM158 -> -39744
A17: =+#REF! -> #REF!
A19: UTILIDAD REEXPRESADA ANTES IMP | H19: =+F13+F17 -> 0
A21: UTILIDAD PLANEADA 8% | B21: =+B12*8% -> 0 | C21: =+C12*8% -> 0 | D21: =+D12*8% -> 0 | E21: =+E12*8% -> 0 | F21: =+F12*8% -> 0
A22: VR A FACTURAR | B22: =-(+C22+D22+E22) -> 353000 | C22: =-75000-27000 -> -102000 | D22: =-23000-9000 -> -32000 | E22: =-165000-54000 -> -219000 | F22: =SUM(B22:E22) -> 0
B23: FT SOCIOS | C23: FT SOCIOS | D23: SOLO ANT EN CE
B24: ARRIENDOS | C24: FT-UTILIDADES | D24: ANT-UTILIDADES | E24: TOTAL
A25: VALORES MES MARZO | B25: 5801891 | C25: 5485827 | D25: =+C25 -> 5485827 | E25: =SUM(B25:D25) -> 16773545
A26: VR MAYO-AGTO | B26: =+B25*8 -> 46415128 | C26: =+C25*8 -> 43886616 | D26: =+D25*8 -> 43886616
B29: ANA MARIA | C29: FERNANDO | H29: ACTUAL | I29: AÑO 2023 ANA | J29: AÑO 2023 FERNANDO
A30: TOTAL VENTAS ACUMULADAS | B30: 34152 | C30: 48152 | H30: INGRESOS | I30: =+B30/3*12 -> 136608 | J30: =+C30/3*12 -> 192608
A31: CTOS Y DEDUCCIONES | B31: =34152+5471 -> 39623 | C31: 28220 | H31: CTOS | I31: =+B31/3*12 -> 158492 | J31: =+C31/3*12 -> 112880
A32: UTILIDAD ANTES DE IMPUESTO | B32: -5471 | C32: 19932 | H32: UTILIDAD | I32: =+I30-I31 -> -21884 | J32: =+J30-J31 -> 79728
B33: =+B32/B30 -> -0.1601956 | C33: =+C32/C30 -> 0.41393919 | H33: IMP | I33: 0 | J33: 3322
J34: =+J33/J32 -> 0.041666667
A35: VENTAS X MES | B35: =+B30/3 -> 11384 | C35: =+C30/3 -> 16050.667
A36: UTILIDAD PROMEDIO MES | B36: =+B32/3 -> -1823.6667 | C36: =+C32/3 -> 6644
H37: PLANEACION | I37: =+I29 -> AÑO 2023 ANA | J37: =+J29 -> AÑO 2023 FERNANDO
H38: INGRESOS | I38: =+I30+(5801*8)+(5486*8) -> 226904 | J38: =+J30 -> 192608
H39: CTOS | I39: =+I31 -> 158492 | J39: =+J31 -> 112880
H40: UTILIDAD | I40: =+I38-I39 -> 68412 | J40: =+J38-J39 -> 79728
H41: IMP | I41: 1121 | J41: =+J33 -> 3322
I42: =+I41/I40 -> 0.016386014 | J42: =+J41/J40 -> 0.041666667
A45: GRUPO DL FACTURA ABRIL 30
A46: FLETES | C46: =+$C$22*0.6 -> -61200 | D46: =+$D$22*0.6 -> -19200 | E46: =+$E$22*0.6 -> -131400
A47: PANES | C47: =+$C$22*0.4 -> -40800 | D47: =+$D$22*0.4 -> -12800 | E47: =+$E$22*0.4 -> -87600
A48: TOTAL | C48: =SUM(C46:C47) -> -102000 | D48: =SUM(D46:D47) -> -32000 | E48: =SUM(E46:E47) -> -219000 | F48: =SUM(C48:E48) -> -353000
...

Sheet 2.E.R.I.MES
B2: =+DATOS!H6 -> GRUPO DE LOLITA SAS | M2: PUNTO DE EQUILIBRIO CONTABLE | P2: PRUEBA DEL PUNTO DE EQUILIBRIO | R2: VERIFICACION CON EL MES | T2: PROYECCION PROXIMO MES
B3: =+DATOS!H7 -> NIT: 900.307.969-5 | M3: INGRESOS | N3: =+C13 -> #REF! | O3: =+N3/N3 -> #REF! | P3: =+M3 -> INGRESOS | Q3: =-+N7 -> #REF! | R3: =+P3 -> INGRESOS | S3: =+N3 -> #REF! | T3: =+P3 -> INGRESOS | U3: 0
B4: ESTADO DE RESULTADOS INTEGRAL MENSUAL | M4: CMV VARIABLE | N4: =+C15 -> 0 | O4: =+N4/N3 -> #REF! | P4: =+M4 -> CMV VARIABLE | Q4: =Q3*O4 -> #REF! | R4: =+P4 -> CMV VARIABLE | S4: =S3*O4 -> #REF! | T4: =+P4 -> CMV VARIABLE | U4: =+U3*O4 -> #REF!
B5: =+DATOS!H8 -> A 30 DE JUNIO DE 2026 Y 2025 | M5: U.DESPUES DE GTOS VBLES | N5: =+N3+N4 -> #REF! | O5: =+N5/N3 -> #REF! | P5: =+M5 -> U.DESPUES DE GTOS VBLES | Q5: =SUM(Q3:Q4) -> #REF! | R5: =+P5 -> U.DESPUES DE GTOS VBLES | S5: =SUM(S3:S4) -> #REF! | T5: =+P5 -> U.DESPUES DE GTOS VBLES | U5: =SUM(U3:U4) -> #REF!
B6: (Cifras Expresadas en Miles de Pesos Colombianos) | M6: GTOS FIJOS | N6: =+C19+C20+C26+C34+C48+C64+C71+C75 -> #REF! | P6: =+M6 -> GTOS FIJOS | Q6: =+N6 -> #REF! | R6: =+P6 -> GTOS FIJOS | S6: =+N6 -> #REF! | T6: =+P6 -> GTOS FIJOS | U6: =+Q6 -> #REF!
M7: P.EQ | N7: =+N6/O5 -> #REF! | P7: =+M7 -> P.EQ | Q7: =+Q5+Q6 -> #REF! | T7: RESULTADO PROYECTADO | U7: =+U5+U6 -> #REF!
C8: =+DATOS!H10 -> 2026-06 | D8: A.V | F8: =+DATOS!H11 -> 2025-06 | G8: A.V | I8: VARIACION | J8: A.H | M8: VENTAS PARA PTO DE.EQ | N8: =+N6/O5 -> #REF! | P8: RESULTADO | Q8: =+Q5+Q6 -> #REF! | R8: RESULTADO | S8: =SUM(S5:S6) -> #REF!
A9: 4120 | B9: Industria manufacturera | C9: =DATOS!#REF! -> #REF! | D9: =C9/$C$13 -> #REF! | F9: =DATOS!#REF! -> #REF! | G9: =+F9/$F$13 -> #REF! | I9: =+C9-F9 -> #REF! | J9: =+I9/F9 -> #REF!
A10: 4121 | B10: Ingresos por exportaciones | C10: =DATOS!#REF! -> #REF! | D10: =C10/$C$13 -> #REF! | F10: =DATOS!#REF! -> #REF! | G10: =+F10/$F$13 -> #REF! | I10: =+C10-F10 -> #REF! | J10: =IFERROR(I10/F10,0%) -> 0
A11: 4135 | B11: Comercio al por mayor y por menor | C11: =DATOS!C89 -> 481388 | D11: =C11/$C$13 -> #REF! | F11: =DATOS!F89 -> 518220 | G11: =+F11/$F$13 -> #REF! | I11: =+C11-F11 -> -36832 | J11: =IFERROR(I11/F11,0%) -> -0.071074061
A12: 4175 | B12: Devoluciones en ventas | C12: =-+DATOS!C95 -> -1237 | D12: =C12/$C$13 -> #REF! | F12: =-DATOS!F95 -> -703 | G12: =+F12/$F$13 -> #REF! | I12: =+C12-F12 -> -534 | J12: =+I12/F12 -> 0.75960171
B13: Ingresos netos | C13: =SUM(C9:C12) -> #REF! | D13: =C13/$C$13 -> #REF! | F13: =SUM(F9:F12) -> #REF! | G13: =+F13/$F$13 -> #REF! | I13: =+C13-F13 -> #REF! | J13: =+I13/F13 -> #REF! | M13: PUNTO DE EQUILIBRIO DE CAJA | N13: =+(N6+C108)/O5 -> #REF!
G14: =+F14/$F$13 -> #REF!
B15: Costo de Materia Prima | C15: =+C16 -> 0 | D15: =C15/$C$13 -> #REF! | F15: =+F16 -> -221817 | G15: =+F15/$F$13 -> #REF! | I15: =+C15-F15 -> 221817 | J15: =+I15/F15 -> -1 | M15: cta 73
B16: Materia Prima | C16: =-DATOS!C201 -> 0 | D16: =C16/$C$13 -> #REF! | F16: =-DATOS!F211 -> -221817 | G16: =+F16/$F$13 -> #REF! | I16: =+C16-F16 -> 221817 | J16: =+I16/F16 -> -1 | M16: AUMENTO CIF (SIN DEPRECIACION)
B17: MARGEN DE CONTRIBUCION 1 | C17: =+C13+C15 -> #REF! | D17: =C17/$C$13 -> #REF! | F17: =+F13+F15 -> #REF! | G17: =+F17/$F$13 -> #REF! | I17: =+C17-F17 -> #REF! | J17: =+I17/F17 -> #REF! | N17: 2024 | O17: 2023 | P17: VARIACION
D18: =C18/$C$13 -> #REF!
A19: 72 | B19: MOD (Mano de obra directa) | C19: =-DATOS!C205 -> -143 | D19: =C19/$C$13 -> #REF! | F19: =+-DATOS!F215 -> 0 | G19: =+F19/$F$13 -> #REF! | I19: =+C19-F19 -> -143 | J19: =IFERROR(I19/F19,0%) -> 0 | M19: HONORARIOS | N19: 8172 | O19: 8740 | P19: =N19-O19 -> -568
A20: 73 | B20: CIF (Costos indirectos de fabricacion) | C20: =-DATOS!C206 -> -84 | D20: =C20/$C$13 -> #REF! | F20: =-DATOS!F216 -> 0 | G20: =+F20/$F$13 -> #REF! | I20: =C20-F20 -> -84 | J20: =IFERROR(I20/F20,0%) -> 0 | M20: IMPUESTOS | N20: 8435 | O20: 10699 | P20: =N20-O20 -> -2264
M21: ARRENDAMIENTOS | N21: 33768 | O21: 28101 | P21: =N21-O21 -> 5667
B22: CMV | C22: =+C15+C19+C20 -> -227 | D22: =C22/$C$13 -> #REF! | F22: =+F15+F19+F20 -> -221817 | G22: =+F22/$F$13 -> #REF! | I22: =C22-F22 -> 221590 | J22: =IFERROR(I22/F22,0%) -> -0.99897663 | M22: CONTRIBUCIONES | N22: -1386 | O22: 848 | P22: =N22-O22 -> -2234
M23: SEGUROS | O23: 993 | P23: =N23-O23 -> -993
B24: GANANCIA BRUTA 2 | C24: =+C17+C19+C20 -> #REF! | D24: =C24/$C$13 -> #REF! | F24: =+F17+F19+F20 -> #REF! | G24: =+F24/$F$13 -> #REF! | I24: =+C24-F24 -> #REF! | J24: =+I24/F24 -> #REF! | M24: SERVICIOS | N24: 34088 | O24: 39185 | P24: =N24-O24 -> -5097
M25: MANTENIMIENTOS | N25: 2890 | O25: 4465 | P25: =N25-O25 -> -1575
B26: Otros Ingresos | C26: =+SUM(C27:C33) -> #REF! | D26: =C26/$C$13 -> #REF! | F26: =SUM(F27:F33) -> #REF! | G26: =+F26/$F$13 -> #REF! | I26: =+C26-F26 -> #REF! | J26: =+I26/F26 -> #REF! | M26: ADECUACIONES | N26: 1973 | O26: 1553 | P26: =N26-O26 -> 420
A27: 4205 | B27: Otras Ventas | C27: =DATOS!#REF! -> #REF! | D27: =C27/$C$13 -> #REF! | F27: =+DATOS!#REF! -> #REF! | G27: =+F27/$F$13 -> #REF! | I27: =+C27-F27 -> #REF! | J27: =+I27/F27 -> #REF! | M27: LEGALES | P27: =N27-O27 -> 0
A28: 4235 | B28: Servicios | C28: =DATOS!C99 -> 899 | D28: =C28/$C$13 -> #REF! | F28: =+DATOS!F99 -> 1421 | G28: =+F28/$F$13 -> #REF! | I28: =+C28-F28 -> -522 | J28: =+I28/F28 -> -0.36734694
A29: 4245 | B29: Utilidad en venta de propiedad planta y equipo | C29: =DATOS!#REF! -> #REF! | D29: =C29/$C$13 -> #REF! | F29: =+DATOS!#REF! -> #REF! | G29: =+F29/$F$13 -> #REF! | I29: =+C29-F29 -> #REF! | J29: =+I29/F29 -> #REF!
A30: 4250 | B30: Recuperacion de costos y gastos | C30: =+DATOS!C101 -> 3 | D30: =C30/$C$13 -> #REF! | F30: =+DATOS!F101 -> 4 | G30: =+F30/$F$13 -> #REF! | I30: =+C30-F30 -> -1 | J30: =IFERROR(I30/F30,0%) -> -0.25
A31: 4255 | B31: Indemnizaciones (incapacidades) | C31: =DATOS!C102 -> 0 | D31: =C31/$C$13 -> #REF! | F31: =+DATOS!F102 -> 0 | G31: =+F31/$F$13 -> #REF! | I31: =+C31-F31 -> 0 | J31: =IFERROR(I31/F31,0%) -> 0
A32: 4265 | B32: Ingresos ejercicios anteriores | C32: =DATOS!C103 -> 0 | D32: =C32/$C$13 -> #REF! | F32: =+DATOS!F103 -> 0 | G32: =+F32/$F$13 -> #REF! | I32: =+C32-F32 -> 0 | J32: =IFERROR(I32/F32,0%) -> 0
A33: 4295 | B33: Diversos | C33: =DATOS!C104 -> 720 | D33: =C33/$C$13 -> #REF! | F33: =+DATOS!F104 -> 519 | G33: =+F33/$F$13 -> #REF! | I33: =+C33-F33 -> 201 | J33: =+I33/F33 -> 0.38728324
B34: Gastos de Ventas | C34: =+SUM(C35:C47) -> #REF! | D34: =C34/$C$13 -> #REF! | F34: =SUM(F35:F47) -> #REF! | G34: =+F34/$F$13 -> #REF! | I34: =+C34-F34 -> #REF! | J34: =+I34/F34 -> #REF! | M34: DIVERSOS | N34: 11486 | O34: 13373 | P34: =N34-O34 -> -1887
A35: 5204 | B35: Aportes sobre la nomina | C35: =-DATOS!C115 -> -1523 | D35: =C35/$C$13 -> #REF! | F35: =-DATOS!F115 -> -1540 | G35: =+F35/$F$13 -> #REF! | I35: =+C35-F35 -> 17 | J35: =+I35/F35 -> -0.011038961
A36: 5205 | B36: Gasto de personal | C36: =-DATOS!C119 -> -50039 | D36: =C36/$C$13 -> #REF! | F36: =-DATOS!F119 -> -51262 | G36: =+F36/$F$13 -> #REF! | I36: =+C36-F36 -> 1223 | J36: =+I36/F36 -> -0.023857828
A37: 5210 | B37: Honorarios | C37: =-DATOS!C138 -> -25821.5 | D37: =C37/$C$13 -> #REF! | F37: =-DATOS!F138 -> -25646 | G37: =+F37/$F$13 -> #REF! | I37: =+C37-F37 -> -175.5 | J37: =+I37/F37 -> 0.0068431724
A38: 5215 | B38: Impuestos | C38: =-DATOS!C142 -> -4810 | D38: =C38/$C$13 -> #REF! | F38: =-DATOS!F142 -> -7525 | G38: =+F38/$F$13 -> #REF! | I38: =+C38-F38 -> 2715 | J38: =+I38/F38 -> -0.36079734
A39: 5220 | B39: Arrendamientos | C39: =-DATOS!C146 -> -85409 | D39: =C39/$C$13 -> #REF! | F39: =-DATOS!F146 -> -65084 | G39: =+F39/$F$13 -> #REF! | I39: =+C39-F39 -> -20325 | J39: =+I39/F39 -> 0.31228873
A40: 5225 | B40: Contribuciones y afiliaciones | C40: =-DATOS!C147 -> -9181 | D40: =C40/$C$13 -> #REF! | F40: =-DATOS!F147 -> -12012 | G40: =+F40/$F$13 -> #REF! | I40: =+C40-F40 -> 2831 | J40: =+I40/F40 -> -0.23568099
A41: 5230 | B41: Seguros | C41: =-DATOS!C148 -> 0 | D41: =C41/$C$13 -> #REF! | F41: =-DATOS!F148 -> 0 | G41: =+F41/$F$13 -> #REF! | I41: =+C41-F41 -> 0 | J41: =IFERROR(I41/F41,0%) -> 0
...

Sheet 1. OBSERVACIONES
A1: =+DATOS!H6 -> GRUPO DE LOLITA SAS
A2: =+DATOS!H7 -> NIT: 900.307.969-5
A3: =+DATOS!H8 -> A 30 DE JUNIO DE 2026 Y 2025
A4: CIFRAS EN MILES DE PESOS
E6: IVA BIMESTRE 1 | F6: 83590
C7: MES | D7: ACUMULADO | E7: IVA BIMESTRE 2 | F7: 81373
E8: IVA BIMESTRE 3 | F8: 61703
B9: RETENCION POR PAGAR | C9: =+DATOS!C52 -> 14503 | E9: IVA BIMESTRE 4 | F9: 0
E10: IVA BIMESTRE 5 | F10: 0
B11: IVA PERIODO | C11: =+SUMIF('6.BP2026'!A:A,2408,'6.BP2026'!H:H)-SUMIF('6.BP2026'!A:A,2408,'6.BP2026'!G:G)-SUMIF('6.BP2026'!A:A,240899,'6.BP2026'!H:H)+SUMIF('6.BP2026'!A:A,240899,'6.BP2026'!G:G) -> 30921 | D11: =-SUMIF('6.BP2026'!A:A,2408,'6.BP2026'!I:I)+F6+F7+F8+F9+F10 -> 226666
B12: PRESION DE IVA | C12: =+C11/('2.E.R.I. MES-ACUMULADO'!CG13) -> 0.064420361 | D12: =+D11/DATOS!D86 -> 0.073106049
A17: 1105 | B17: CAJA: | C17: =+DATOS!C6 -> 462620
B19: DETALLE CAJAS | C19: SALDO | D19: BASE | E19: DIFERENCIA | F19: OBSERVACION
B20: CAJA TRANSITORIA | C20: 456921 | D20: 0 | E20: =C20-D20 -> 456921 | F20: Caja de ajustes
B21: CAJA UNICENTRO | C21: 300 | D21: 300 | E21: =C21-D21 -> 0
B22: CAJAS MENORES | C22: 3900 | D22: 3900 | E22: =C22-D22 -> 0
B23: CAJA PUNTO CLAVE | C23: 300 | D23: 300 | E23: =C23-D23 -> 0
B24: CAJA LIBERTAD | C24: 300 | D24: 300 | E24: =C24-D24 -> 0
B25: CAJA PLAZA FABRICATO | C25: 0 | D25: 0 | E25: =C25-D25 -> 0
B26: CAJA MONTERREY | C26: 300 | D26: 300 | E26: =C26-D26 -> 0
B27: CAJA CLINICA PRADO | C27: 300 | D27: 300 | E27: =C27-D27 -> 0
B28: CAJA TORRE MEDICA | C28: 300 | D28: 300 | E28: =C28-D28 -> 0
B29: DIFERENCIA | C29: =SUM(C20:C28) -> 462621 | D29: =SUM(D20:D28) -> 5700 | E29: =SUM(E20:E28) -> 456921
C30: =+C17-C29 -> -1
A32: 1110 | B32: BANCOS | C32: =+DATOS!C7 -> 34966 | D32: OBSERVACION
B33: CTA B.OCCIDENTE 9426 | C33: 867 | D33: Conciliada con extracto
B34: HELM BANK - ITAU 1190 | C34: 36 | D34: Conciliada con extracto
B35: CTA B.BOGOTA 3199 | C35: 730 | D35: Conciliada con extracto
B36: HELMBANK - ITAU 2545 | C36: 94 | D36: Conciliada con extracto
B37: HELMBANK - ITAU 2624 | C37: 2502 | D37: Conciliada con extracto
B38: BANCO COLPATRIA 3358 | C38: 17 | D38: Conciliada con extracto
B39: CUENTA PUENTE 4451 BBIA | C39: 30721 | D39: Conciliada con extracto
C40: =SUM(C33:C39)-C32 -> 1
A42: 1120 | B42: BANCOS | C42: =+DATOS!C8 -> 37524 | D42: OBSERVACION
B43: CTA BANCOLOMBIA AHO 8271 | C43: 10 | D43: Conciliada con extracto.
B44: BANCO DAVIVIENDA 7872 | C44: 37515 | D44: Conciliada con extracto.
C45: =SUM(C43:C44)-C42 -> 1
A47: 1130 | B47: FIDUCUENTA | C47: =+DATOS!C9 -> 41670 | D47: OBSERVACION
B48: BANCO DE DAVIVIENDA CTA 3122 | C48: 420 | D48: Conciliada con extracto.
B49: BANCOLOMBIA | C49: 41250 | D49: Conciliada con extracto.
...

Sheet 2.E.R.I. MES-ACUMULADO
B1: =+DATOS!H6 -> GRUPO DE LOLITA SAS
B2: =+DATOS!H7 -> NIT: 900.307.969-5
B3: ESTADO DE RESULTADOS INTEGRAL ACUMULADO
B4: =+DATOS!H8 -> A 30 DE JUNIO DE 2026 Y 2025
B5: (Cifras Expresadas en Miles de Pesos Colombianos)
D8: MONTERREY (1004) | E8: TORRE MEDICA | F8: PUNTO CLAVE | G8: MAYORCA PISO 4 | H8: MEGAPLAZA | I8: CLINICA DEL PRADO | J8: LA LIBERTAD | K8: PLAZA FABRICATO | L8: UNICENTRO | M8: 2025-12 | N8: A.V | P8: MONTERREY (1004) | Q8: TORRE MEDICA | R8: PUNTO CLAVE | S8: MAYORCA PISO 4 | T8: MEGAPLAZA | U8: CLINICA DEL PRADO | V8: LA LIBERTAD | W8: PLAZA FABRICATO | X8: UNICENTRO | Y8: 2026-01 | Z8: A.V | AB8: MONTERREY (1004) | AC8: TORRE MEDICA | AD8: PUNTO CLAVE | AE8: MAYORCA PISO 4 | AF8: MEGAPLAZA | AG8: CLINICA DEL PRADO | AH8: LA LIBERTAD | AI8: PLAZA FABRICATO | AJ8: UNICENTRO | AK8: 2026-02 | AL8: A.V | AN8: MONTERREY (1004) | AO8: TORRE MEDICA | AP8: PUNTO CLAVE | AQ8: MAYORCA PISO 4 | AR8: MEGAPLAZA | AS8: CLINICA DEL PRADO | AT8: LA LIBERTAD | AU8: PLAZA FABRICATO | AV8: UNICENTRO | AW8: 2026-03 | AX8: A.V | AZ8: MONTERREY (1004) | BA8: TORRE MEDICA | BB8: PUNTO CLAVE | BC8: MAYORCA PISO 4 | BD8: MEGAPLAZA | BE8: CLINICA DEL PRADO | BF8: LA LIBERTAD | BG8: PLAZA FABRICATO | BH8: UNICENTRO | BI8: 2026-04 | BJ8: A.V | BL8: MONTERREY (1004) | BM8: TORRE MEDICA | BN8: PUNTO CLAVE | BO8: MAYORCA PISO 4 | BP8: MEGAPLAZA | BQ8: CLINICA DEL PRADO | BR8: LA LIBERTAD | BS8: PLAZA FABRICATO | BT8: UNICENTRO | BU8: 2026-05 | BV8: A.V | BX8: MONTERREY (1004) | BY8: TORRE MEDICA | BZ8: PUNTO CLAVE | CA8: MAYORCA PISO 4 | CB8: MEGAPLAZA | CC8: CLINICA DEL PRADO | CD8: LA LIBERTAD | CE8: PLAZA FABRICATO | CF8: UNICENTRO | CG8: 2026-06 | CH8: A.V | CJ8: VARIACION MES 2025 | CK8: A.H | CM8: ACUMULADO 2026 | CN8: A.V | CP8: =+DATOS!H11 -> 2025-06 | CQ8: A.V | CS8: ACUMULADO 2025 | CT8: A.V | CV8: VARIACION ACUMULADO 2024-2025 | CW8: A.H
A9: 4120 | B9: Fletes | D9: 0 | E9: 0 | F9: 0 | G9: 0 | H9: 0 | I9: 0 | J9: 0 | K9: 0 | L9: 0 | M9: =SUM(D9:L9) -> 0 | N9: =+M9/M$13 -> 0 | P9: 0 | Q9: 0 | R9: 0 | S9: 0 | T9: 0 | U9: 0 | V9: 0 | W9: 0 | X9: 0 | Y9: =SUM(P9:X9) -> 0 | Z9: =+Y9/Y$13 -> 0 | AB9: 0 | AC9: 0 | AD9: 0 | AE9: 0 | AF9: 0 | AG9: 0 | AH9: 0 | AI9: 0 | AJ9: 0 | AK9: =SUM(AB9:AJ9) -> 0 | AL9: =+AK9/AK$13 -> 0 | AN9: 0 | AO9: 0 | AP9: 0 | AQ9: 0 | AR9: 0 | AS9: 0 | AT9: 0 | AU9: 0 | AV9: 0 | AW9: =SUM(AN9:AV9) -> 0 | AX9: =+AW9/AW$13 -> 0 | AZ9: 0 | BA9: 0 | BB9: 0 | BC9: 0 | BD9: 2150 | BE9: 0 | BF9: 0 | BG9: 0 | BH9: 0 | BI9: =SUM(AZ9:BH9) -> 2150 | BJ9: =+BI9/BI$13 -> 0.0043351669 | BL9: 0 | BM9: 0 | BN9: 0 | BO9: 0 | BP9: 0 | BQ9: 0 | BR9: 0 | BS9: 0 | BT9: 0 | BU9: =SUM(BL9:BT9) -> 0 | BV9: =+BU9/BU$13 -> 0 | BX9: 0 | BY9: 150 | BZ9: 0 | CA9: 0 | CB9: 0 | CC9: 0 | CD9: 0 | CE9: 0 | CF9: 0 | CG9: =SUM(BX9:CF9) -> 150 | CH9: =+CG9/CG$13 -> 0.00031250781 | CJ9: =+CG9-BU9 -> 150 | CK9: =IFERROR(+CJ9/BU9,0%) -> 0 | CM9: =+DATOS!D88 -> 2300 | CN9: =+CM9/CM$13 -> 0.00075606525
A10: 4135 | B10: Comercio al por mayor y por menor | D10: 79613 | E10: 55945 | F10: 43382 | G10: 99947 | H10: 121937 | I10: 84160 | J10: 66193 | K10: 128 | L10: 54110 | M10: =SUM(D10:L10) -> 605415 | N10: =+M10/M$13 -> 1.1993902 | P10: 75219 | Q10: 50610 | R10: 36913 | S10: 78052 | T10: 106919 | U10: 77091 | V10: 57803 | W10: 0 | X10: 50111 | Y10: =SUM(P10:X10) -> 532718 | Z10: =+Y10/Y$13 -> 1.0122292 | AB10: 66066 | AC10: 56451 | AD10: 40250 | AE10: 61467 | AF10: 85050 | AG10: 88096 | AH10: 67386 | AI10: 0 | AJ10: 42596 | AK10: =SUM(AB10:AJ10) -> 507362 | AL10: =+AK10/AK$13 -> 0.99143519 | AN10: 73018 | AO10: 60645 | AP10: 41896 | AQ10: 66667 | AR10: 87219 | AS10: 89204 | AT10: 65645 | AU10: 0 | AV10: 47848 | AW10: =SUM(AN10:AV10) -> 532142 | AX10: =+AW10/AW$13 -> 1.0021054 | AZ10: 60593 | BA10: 58536 | BB10: 39617 | BC10: 62449 | BD10: 86837 | BE10: 83657 | BF10: 61022 | BG10: 0 | BH10: 42115 | BI10: =SUM(AZ10:BH10) -> 494826 | BJ10: =+BI10/BI$13 -> 0.99774571 | BL10: 57292 | BM10: 56023 | BN10: 36128 | BO10: 63856 | BP10: 95263 | BQ10: 82402 | BR10: 61526 | BS10: 0 | BT10: 45700 | BU10: =SUM(BL10:BT10) -> 498190 | BV10: =+BU10/BU$13 -> 1.0022451 | BX10: 60078 | BY10: 55981 | BZ10: 36240 | CA10: 65529 | CB10: 78684 | CC10: 81938 | CD10: 57110 | CE10: 0 | CF10: 45828 | CG10: =SUM(BX10:CF10) -> 481388 | CH10: =+CG10/CG$13 -> 1.0029167 | CJ10: =+CG10-BU10 -> -16802 | CK10: =IFERROR(+CJ10/BU10,0%) -> -0.033726088 | CM10: =SUM(DATOS!D89:D94)-CM11 -> 3046631.5 | CN10: =+CM10/CM$13 -> 1.001501 | CP10: =+DATOS!F89+DATOS!F90+DATOS!F91+DATOS!F92+DATOS!F93 -> 518352.5 | CQ10: =+CP10/CP$13 -> 1.0061258 | CS10: =+DATOS!G89+DATOS!G90+DATOS!G91+DATOS!G92+DATOS!G93 -> 2938925.5 | CT10: =+CS10/CS$13 -> 0.99999762 | CV10: =+CM10-CS10 -> 107706 | CW10: =+IFERROR(CV10/CS10,0) -> 0.036648088
B11: Ingreso Ajuste Henkost | D11: -12 | E11: -23 | F11: -31 | G11: -32 | H11: -15 | I11: -33 | J11: -20 | K11: 0 | L11: -26 | M11: =SUM(D11:L11) -> -192 | N11: =+M11/M$13 -> -0.00038037201 | P11: -514 | Q11: -335 | R11: -409 | S11: -697 | T11: -1830 | U11: -963 | V11: -514 | W11: 0 | X11: -267 | Y11: =SUM(P11:X11) -> -5529 | Z11: =+Y11/Y$13 -> -0.010505774 | AB11: 532 | AC11: 410 | AD11: 326 | AE11: 540 | AF11: 1683 | AG11: 963 | AH11: 465 | AI11: 0 | AJ11: 285 | AK11: =SUM(AB11:AJ11) -> 5204 | AL11: =+AK11/AK$13 -> 0.010169127 | AN11: 35 | AO11: 0 | AP11: -89 | AQ11: -136 | AR11: 18 | AS11: 0 | AT11: 24 | AU11: 0 | AV11: -98 | AW11: =SUM(AN11:AV11) -> -246 | AX11: =+AW11/AW$13 -> -0.0004632559 | AZ11: 171 | BA11: -95 | BB11: -73 | BC11: -263 | BD11: -9 | BE11: 0 | BF11: 26 | BG11: 0 | BH11: 78 | BI11: =SUM(AZ11:BH11) -> -165 | BJ11: =+BI11/BI$13 -> -0.00033269885 | BL11: 29 | BM11: 0 | BN11: 43 | BO11: 184 | BP11: 118 | BQ11: 0 | BR11: -182 | BS11: 0 | BT11: -10 | BU11: =SUM(BL11:BT11) -> 182 | BV11: =+BU11/BU$13 -> 0.00036614267 | BX11: -29 | BY11: 0 | BZ11: -43 | CA11: -141 | CB11: -133 | CC11: 0 | CD11: 50 | CE11: 0 | CF11: -16 | CG11: =SUM(BX11:CF11) -> -312 | CH11: =+CG11/CG$13 -> -0.00065001625 | CJ11: =+CG11-BU11 -> -494 | CK11: =IFERROR(+CJ11/BU11,0%) -> -2.7142857 | CM11: =+Y11+AK11+CG11+AW11+BI11+BU11 -> -866 | CN11: =+CM11/CM$13 -> -0.000284675 | CP11: =+DATOS!F94 -> -2453 | CQ11: =+CP11/CP$13 -> -0.0047612901 | CS11: =+DATOS!G94 -> 4446 | CT11: =+CS11/CS$13 -> 0.0015127942 | CV11: =+CM11-CS11 -> -5312 | CW11: =+IFERROR(CV11/CS11,0) -> -1.1947818
A12: 4175 | B12: Devoluciones en ventas | D12: 0 | E12: -87 | F12: -38 | G12: -41 | H12: -100085 | I12: -123 | J12: 0 | K12: 0 | L12: -80 | M12: =SUM(D12:L12) -> -100454 | N12: =+M12/M$13 -> -0.19900984 | P12: 0 | Q12: -35 | R12: -134 | S12: -51 | T12: -446 | U12: -54 | V12: -116 | W12: 0 | X12: -71 | Y12: =SUM(P12:X12) -> -907 | Z12: =+Y12/Y$13 -> -0.0017234106 | AB12: 0 | AC12: -114 | AD12: -19 | AE12: -236 | AF12: -273 | AG12: -130 | AH12: -49 | AI12: 0 | AJ12: 0 | AK12: =SUM(AB12:AJ12) -> -821 | AL12: =+AK12/AK$13 -> -0.0016043146 | AN12: 0 | AO12: -167 | AP12: -155 | AQ12: -260 | AR12: -77 | AS12: -148 | AT12: -13 | AU12: 0 | AV12: -52 | AW12: =SUM(AN12:AV12) -> -872 | AX12: =+AW12/AW$13 -> -0.0016421103 | AZ12: 0 | BA12: -95 | BB12: -220 | BC12: -321 | BD12: -52 | BE12: 0 | BF12: -135 | BG12: 0 | BH12: -44 | BI12: =SUM(AZ12:BH12) -> -867 | BJ12: =+BI12/BI$13 -> -0.0017481812 | BL12: -29 | BM12: -201 | BN12: -89 | BO12: -401 | BP12: -24 | BQ12: -90 | BR12: -361 | BS12: 0 | BT12: -103 | BU12: =SUM(BL12:BT12) -> -1298 | BV12: =+BU12/BU$13 -> -0.0026112812 | BX12: -218 | BY12: -116 | BZ12: -151 | CA12: -407 | CB12: -199 | CC12: -41 | CD12: -78 | CE12: 0 | CF12: -28 | CG12: =SUM(BX12:CF12) -> -1238 | CH12: =+CG12/CG$13 -> -0.0025792311 | CJ12: =+CG12-BU12 -> 60 | CK12: =IFERROR(+CJ12/BU12,0%) -> -0.046224961 | CM12: =-DATOS!D95 -> -6000 | CN12: =+CM12/CM$13 -> -0.0019723441 | CP12: =-DATOS!F95 -> -703 | CQ12: =+CP12/CP$13 -> -0.0013645279 | CS12: =-DATOS!G95 -> -4439 | CT12: =+CS12/CS$13 -> -0.0015104124 | CV12: =+CM12-CS12 -> -1561 | CW12: =+IFERROR(CV12/CS12,0) -> 0.35165578
B13: INGRESOS NETOS | D13: =SUM(D9:D12) -> 79601 | E13: =SUM(E9:E12) -> 55835 | F13: =SUM(F9:F12) -> 43313 | G13: =SUM(G9:G12) -> 99874 | H13: =SUM(H9:H12) -> 21837 | I13: =SUM(I9:I12) -> 84004 | J13: =SUM(J9:J12) -> 66173 | K13: =SUM(K9:K12) -> 128 | ... M13: =SUM(M9:M12) -> 504769 | N13: =+M13/M$13 -> 1 | P13: =SUM(P9:P12) -> 74705 | Q13: =SUM(Q9:Q12) -> 50240 | R13: =SUM(R9:R12) -> 36370 | S13: =SUM(S9:S12) -> 77304 | T13: =SUM(T9:T12) -> 104643 | U13: =SUM(U9:U12) -> 76074 | V13: =SUM(V9:V12) -> 57173 | W13: =SUM(W9:W12) -> 0 | ... Y13: =SUM(Y9:Y12) -> 526282 | Z13: =+Y13/Y$13 -> 1 | AB13: =SUM(AB9:AB12) -> 66598 | AC13: =SUM(AC9:AC12) -> 56747 | AD13: =SUM(AD9:AD12) -> 40557 | AE13: =SUM(AE9:AE12) -> 61771 | AF13: =SUM(AF9:AF12) -> 86460 | AG13: =SUM(AG9:AG12) -> 88929 | AH13: =SUM(AH9:AH12) -> 67802 | AI13: =SUM(AI9:AI12) -> 0 | ... AK13: =SUM(AK9:AK12) -> 511745 | AL13: =+AK13/AK$13 -> 1 | AN13: =SUM(AN9:AN12) -> 73053 | AO13: =SUM(AO9:AO12) -> 60478 | AP13: =SUM(AP9:AP12) -> 41652 | AQ13: =SUM(AQ9:AQ12) -> 66271 | AR13: =SUM(AR9:AR12) -> 87160 | AS13: =SUM(AS9:AS12) -> 89056 | AT13: =SUM(AT9:AT12) -> 65656 | AU13: =SUM(AU9:AU12) -> 0 | ... AW13: =SUM(AW9:AW12) -> 531024 | AX13: =+AW13/AW$13 -> 1 | AZ13: =SUM(AZ9:AZ12) -> 60764 | BA13: =SUM(BA9:BA12) -> 58346 | BB13: =SUM(BB9:BB12) -> 39324 | BC13: =SUM(BC9:BC12) -> 61865 | BD13: =SUM(BD9:BD12) -> 88926 | BE13: =SUM(BE9:BE12) -> 83657 | BF13: =SUM(BF9:BF12) -> 60913 | BG13: =SUM(BG9:BG12) -> 0 | ... BI13: =SUM(BI9:BI12) -> 495944 | BJ13: =+BI13/BI$13 -> 1 | BL13: =SUM(BL9:BL12) -> 57292 | BM13: =SUM(BM9:BM12) -> 55822 | BN13: =SUM(BN9:BN12) -> 36082 | BO13: =SUM(BO9:BO12) -> 63639 | BP13: =SUM(BP9:BP12) -> 95357 | BQ13: =SUM(BQ9:BQ12) -> 82312 | BR13: =SUM(BR9:BR12) -> 60983 | BS13: =SUM(BS9:BS12) -> 0 | ... BU13: =SUM(BU9:BU12) -> 497074 | BV13: =+BU13/BU$13 -> 1 | BX13: =SUM(BX9:BX12) -> 59831 | BY13: =SUM(BY9:BY12) -> 56015 | BZ13: =SUM(BZ9:BZ12) -> 36046 | CA13: =SUM(CA9:CA12) -> 64981 | CB13: =SUM(CB9:CB12) -> 78352 | CC13: =SUM(CC9:CC12) -> 81897 | CD13: =SUM(CD9:CD12) -> 57082 | CE13: =SUM(CE9:CE12) -> 0 | ... CG13: =SUM(CG9:CG12) -> 479988 | CH13: =+CG13/CG$13 -> 1 | CJ13: =+CG13-BU13 -> -17086 | CK13: =IFERROR(+CJ13/BU13,0%) -> -0.034373152 | CM13: =SUM(CM9:CM12) -> 3042065.5 | CN13: =+CM13/CM$13 -> 1 | CP13: =SUM(CP10:CP12) -> 515196.5 | CQ13: =+CP13/CP$13 -> 1 | CR13: =+CP13-DATOS!F87 -> 0 | CS13: =SUM(CS10:CS12) -> 2938932.5 | CT13: =+CS13/CS$13 -> 1 | CV13: =+CM13-CS13 -> 103133 | CW13: =+IFERROR(CV13/CS13,0) -> 0.035091993
CP14: =+CP15+DATOS!F212 -> 1 | CS14: =+CS15+DATOS!G212 -> 1
A15: 6 | B15: CMV | D15: =-(D16+D17-D18) -> -29927 | E15: =-(E16+E17-E18) -> -27561 | F15: =-(F16+F17-F18) -> -18660 | G15: =-(G16+G17-G18) -> -39572 | H15: =-(H16+H17-H18) -> -43047 | I15: =-(I16+I17-I18) -> -37823 | J15: =-(J16+J17-J18) -> -27747 | K15: =-(K16+K17-K18) -> 0 | ... M15: =-(M16+M17-M18) -> -248528 | N15: =+M15/M$13 -> -0.49235987 | P15: =-(P16+P17-P18) -> -26742 | Q15: =-(Q16+Q17-Q18) -> -22587 | R15: =-(R16+R17-R18) -> -14569 | S15: =-(S16+S17-S18) -> -27304 | T15: =-(T16+T17-T18) -> -36585 | U15: =-(U16+U17-U18) -> -32983 | V15: =-(V16+V17-V18) -> -25133 | W15: =-(W16+W17-W18) -> 0 | ... Y15: =-(Y16+Y17-Y18) -> -205215 | Z15: =+Y15/Y$13 -> -0.38993353 | AB15: =-(AB16+AB17-AB18) -> -26091 | AC15: =-(AC16+AC17-AC18) -> -28050 | AD15: =-(AD16+AD17-AD18) -> -16919 | AE15: =-(AE16+AE17-AE18) -> -25310 | AF15: =-(AF16+AF17-AF18) -> -32754 | AG15: =-(AG16+AG17-AG18) -> -42645 | AH15: =-(AH16+AH17-AH18) -> -31887 | AI15: =-(AI16+AI17-AI18) -> 0 | ... AK15: =-(AK16+AK17-AK18) -> -224232 | AL15: =+AK15/AK$13 -> -0.43817135 | AN15: =-(AN16+AN17-AN18) -> -29508 | AO15: =-(AO16+AO17-AO18) -> -28554 | AP15: =-(AP16+AP17-AP18) -> -19049 | AQ15: =-(AQ16+AQ17-AQ18) -> -25775 | AR15: =-(AR16+AR17-AR18) -> -32385 | AS15: =-(AS16+AS17-AS18) -> -41083 | AT15: =-(AT16+AT17-AT18) -> -28494 | AU15: =-(AU16+AU17-AU18) -> 0 | ... AW15: =-(AW16+AW17-AW18) -> -224593 | AX15: =+AW15/AW$13 -> -0.42294322 | AZ15: =-(AZ16+AZ17-AZ18) -> -25403 | BA15: =-(BA16+BA17-BA18) -> -28195 | BB15: =-(BB16+BB17-BB18) -> -17528 | BC15: =-(BC16+BC17-BC18) -> -24913 | BD15: =-(BD16+BD17-BD18) -> -32295 | BE15: =-(BE16+BE17-BE18) -> -38201 | BF15: =-(BF16+BF17-BF18) -> -27079 | BG15: =-(BG16+BG17-BG18) -> 0 | ... BI15: =-(BI16+BI17-BI18) -> -214448 | BJ15: =+BI15/BI$13 -> -0.43240366 | BL15: =-(BL16+BL17-BL18) -> -23715 | BM15: =-(BM16+BM17-BM18) -> -26391 | BN15: =-(BN16+BN17-BN18) -> -15247 | BO15: =-(BO16+BO17-BO18) -> -25222 | BP15: =-(BP16+BP17-BP18) -> -35192 | BQ15: =-(BQ16+BQ17-BQ18) -> -37970 | BR15: =-(BR16+BR17-BR18) -> -27474 | BS15: =-(BS16+BS17-BS18) -> 0 | ... BU15: =-(BU16+BU17-BU18) -> -210791 | BV15: =+BU15/BU$13 -> -0.42406362 | BX15: =-(BX16+BX17-BX18) -> -22228 | BY15: =-(BY16+BY17-BY18) -> -25858 | BZ15: =-(BZ16+BZ17-BZ18) -> -15501 | CA15: =-(CA16+CA17-CA18) -> -25223 | CB15: =-(CB16+CB17-CB18) -> -29512 | CC15: =-(CC16+CC17-CC18) -> -37240 | CD15: =-(CD16+CD17-CD18) -> -25151 | CE15: =-(CE16+CE17-CE18) -> 0 | ... CG15: =-(CG16+CG17-CG18) -> -199859 | CH15: =+CG15/CG$13 -> -0.41638333 | CJ15: =+CG15-BU15 -> 10932 | CK15: =IFERROR(+CJ15/BU15,0%) -> -0.051861797 | CM15: =-(CM16+CM17-CM18) -> -1279138 | CN15: =+CM15/CM$13 -> -0.42048339 | CP15: =-(CP16+CP17-CP18) -> -221816 | CQ15: =+CP15/CP$13 -> -0.4305464 | CR15: =+CP15+DATOS!F212 -> 1 | CS15: =-(CS16+CS17-CS18) -> -1241064 | CT15: =+CS15/CS$13 -> -0.42228394 | CV15: =+CM15-CS15 -> -38074 | CW15: =+IFERROR(CV15/CS15,0) -> 0.030678515
A16: 14 | B16: Inventario inicial | D16: 7928 | E16: 11481 | F16: 8062 | G16: 9639 | H16: 8472 | I16: 14525 | J16: 9215 | K16: 0 | L16: 8636 | M16: =SUM(D16:L16) -> 77958 | N16: =+M16/M$13 -> 0.15444292 | P16: 7673 | Q16: 7927 | R16: 8345 | S16: 10712 | T16: 11516 | U16: 13198 | V16: 9559 | W16: 0 | X16: 9102 | Y16: =SUM(P16:X16) -> 78032 | Z16: =+Y16/Y$13 -> 0.14827032 | AB16: 7951 | AC16: 11554 | AD16: 8986 | AE16: 13481 | AF16: 12941 | AG16: 16261 | AH16: 9926 | AI16: 0 | AJ16: 9777 | AK16: =SUM(AB16:AJ16) -> 90877 | AL16: =+AK16/AK$13 -> 0.17758259 | AN16: 8244 | AO16: 10331 | AP16: 8193 | AQ16: 11096 | AR16: 11019 | AS16: 14952 | AT16: 9277 | AU16: 0 | AV16: 9414 | AW16: =SUM(AN16:AV16) -> 82526 | AX16: =+AW16/AW$13 -> 0.15540917 | AZ16: 8882 | BA16: 10926 | BB16: 8362 | BC16: 10210 | BD16: 11617 | BE16: 12673 | BF16: 7939 | BG16: 0 | BH16: 9642 | BI16: =SUM(AZ16:BH16) -> 80251 | BJ16: =+BI16/BI$13 -> 0.16181464 | BL16: 10032 | BM16: 10668 | BN16: 7927 | BO16: 11078 | BP16: 14210 | BQ16: 12520 | BR16: 8749 | BS16: 0 | BT16: 8102 | BU16: =SUM(BL16:BT16) -> 83286 | BV16: =+BU16/BU$13 -> 0.16755252 | BX16: 7337 | BY16: 10880 | BZ16: 8082 | CA16: 10491 | CB16: 9193 | CC16: 12051 | CD16: 9458 | CE16: 0 | CF16: 7508 | CG16: =SUM(BX16:CF16) -> 75000 | CH16: =+CG16/CG$13 -> 0.15625391 | CJ16: =+CG16-BU16 -> -8286 | CK16: =IFERROR(+CJ16/BU16,0%) -> -0.099488509 | CM16: =+Y16 -> 78032 | CN16: =+CM16/CM$13 -> 0.025650993 | CP16: =+SUMIF('7.BP2025'!A:A,14,'7.BP2025'!F:F) -> 92469 | CQ16: =+CP16/CP$13 -> 0.17948297 | CS16: 70972 | CT16: =+CS16/CS$13 -> 0.024148904 | CV16: =+CM16-CS16 -> 7060 | CW16: =+IFERROR(CV16/CS16,0) -> 0.09947585
A17: 14 | B17: Compras | D17: 29672 | E17: 24007 | F17: 18943 | G17: 40645 | H17: 46091 | I17: 36496 | J17: 28091 | K17: 0 | L17: 24657 | M17: =SUM(D17:L17) -> 248602 | N17: =+M17/M$13 -> 0.49250647 | P17: 27020 | Q17: 26214 | R17: 15210 | S17: 30073 | T17: 38010 | U17: 36046 | V17: 25500 | W17: 0 | X17: 19987 | Y17: =SUM(P17:X17) -> 218060 | Z17: =+Y17/Y$13 -> 0.4143406 | AB17: 26384 | AC17: 26827 | AD17: 16126 | AE17: 22925 | AF17: 30832 | AG17: 41336 | AH17: 31238 | AI17: 0 | AJ17: 20213 | AK17: =SUM(AB17:AJ17) -> 215881 | AL17: =+AK17/AK$13 -> 0.42185268 | AN17: 30146 | AO17: 29149 | AP17: 19218 | AQ17: 24889 | AR17: 32983 | AS17: 38804 | AT17: 27156 | AU17: 0 | AV17: 19973 | AW17: =SUM(AN17:AV17) -> 222318 | AX17: =+AW17/AW$13 -> 0.41865904 | AZ17: 26553 | BA17: 27937 | BB17: 17093 | BC17: 25781 | BD17: 34888 | BE17: 38048 | BF17: 27889 | BG17: 0 | BH17: 19294 | BI17: =SUM(AZ17:BH17) -> 217483 | BJ17: =+BI17/BI$13 -> 0.4385233 | BL17: 21020 | BM17: 26603 | BN17: 15402 | BO17: 24635 | BP17: 30175 | BQ17: 37501 | BR17: 28183 | BS17: 0 | BT17: 18986 | BU17: =SUM(BL17:BT17) -> 202505 | BV17: =+BU17/BU$13 -> 0.40739407 | BX17: 22239 | BY17: 26260 | BZ17: 15794 | CA17: 26611 | CB17: 31352 | CC17: 36432 | CD17: 23782 | CE17: 0 | CF17: 20638 | CG17: =SUM(BX17:CF17) -> 203108 | CH17: =+CG17/CG$13 -> 0.42315225 | CJ17: =+CG17-BU17 -> 603 | CK17: =IFERROR(+CJ17/BU17,0%) -> 0.0029777043 | CM17: =+Y17+AK17+CG17+AW17+BI17+BU17 -> 1279355 | CN17: =+CM17/CM$13 -> 0.42055472 | CP17: =+SUMIF('7.BP2025'!A:A,1435,'7.BP2025'!G:G)-SUMIF('7.BP2025'!A:A,1435,'7.BP2025'!H:H)+SUMIF('7.BP2025'!A:A,143599,'7.BP2025'!H:H)/2 -> 211197 | CQ17: =+CP17/CP$13 -> 0.40993485 | CS17: =184996-6-301+199683+206470+204133+245770+211197 -> 1251942 | CT17: =+CS17/CS$13 -> 0.42598529 | CV17: =+CM17-CS17 -> 27413 | CW17: =+IFERROR(CV17/CS17,0) -> 0.021896382
A18: 14 | B18: Inventario final | D18: 7673 | E18: 7927 | F18: 8345 | G18: 10712 | H18: 11516 | I18: 13198 | J18: 9559 | K18: 0 | L18: 9102 | M18: =SUM(D18:L18) -> 78032 | N18: =+M18/M$13 -> 0.15458953 | P18: 7951 | Q18: 11554 | R18: 8986 | S18: 13481 | T18: 12941 | U18: 16261 | V18: 9926 | W18: 0 | X18: 9777 | Y18: =SUM(P18:X18) -> 90877 | Z18: =+Y18/Y$13 -> 0.17267739 | AB18: 8244 | AC18: 10331 | AD18: 8193 | AE18: 11096 | AF18: 11019 | AG18: 14952 | AH18: 9277 | AI18: 0 | AJ18: 9414 | AK18: =SUM(AB18:AJ18) -> 82526 | AL18: =+AK18/AK$13 -> 0.16126391 | AN18: 8882 | AO18: 10926 | AP18: 8362 | AQ18: 10210 | AR18: 11617 | AS18: 12673 | AT18: 7939 | AU18: 0 | AV18: 9642 | AW18: =SUM(AN18:AV18) -> 80251 | AX18: =+AW18/AW$13 -> 0.151125 | AZ18: 10032 | BA18: 10668 | BB18: 7927 | BC18: 11078 | BD18: 14210 | BE18: 12520 | BF18: 8749 | BG18: 0 | BH18: 8102 | BI18: =SUM(AZ18:BH18) -> 83286 | BJ18: =+BI18/BI$13 -> 0.16793428 | BL18: 7337 | BM18: 10880 | BN18: 8082 | BO18: 10491 | BP18: 9193 | BQ18: 12051 | BR18: 9458 | BS18: 0 | BT18: 7508 | BU18: =SUM(BL18:BT18) -> 75000 | BV18: =+BU18/BU$13 -> 0.15088297 | BX18: 7348 | BY18: 11282 | BZ18: 8375 | CA18: 11879 | CB18: 11033 | CC18: 11243 | CD18: 8089 | CE18: 0 | CF18: 9000 | CG18: =SUM(BX18:CF18) -> 78249 | CH18: =+CG18/CG$13 -> 0.16302283 | CJ18: =+CG18-BU18 -> 3249 | CK18: =IFERROR(+CJ18/BU18,0%) -> 0.04332 | CM18: =+CG18 -> 78249 | CN18: =+CM18/CM$13 -> 0.025722326 | CP18: =+SUMIF('7.BP2025'!A:A,14,'7.BP2025'!I:I) -> 81850 | CQ18: =+CP18/CP$13 -> 0.15887142 | CS18: =+CP18 -> 81850 | CT18: =+CS18/CS$13 -> 0.027850248 | CV18: =+CM18-CS18 -> -3601 | CW18: =+IFERROR(CV18/CS18,0) -> -0.043995113
B20: GANANCIA BRUTA | D20: =+D13+D15 -> 49674 | E20: =+E13+E15 -> 28274 | F20: =+F13+F15 -> 24653 | G20: =+G13+G15 -> 60302 | H20: =+H13+H15 -> -21210 | I20: =+I13+I15 -> 46181 | J20: =+J13+J15 -> 38426 | K20: =+K13+K15 -> 128 | ... M20: =+M13+M15 -> 256241 | N20: =+M20/M$13 -> 0.50764013 | P20: =+P13+P15 -> 47963 | Q20: =+Q13+Q15 -> 27653 | R20: =+R13+R15 -> 21801 | S20: =+S13+S15 -> 50000 | T20: =+T13+T15 -> 68058 | U20: =+U13+U15 -> 43091 | V20: =+V13+V15 -> 32040 | W20: =+W13+W15 -> 0 | ... Y20: =+Y13+Y15 -> 321067 | Z20: =+Y20/Y$13 -> 0.61006647 | AB20: =+AB13+AB15 -> 40507 | AC20: =+AC13+AC15 -> 28697 | AD20: =+AD13+AD15 -> 23638 | AE20: =+AE13+AE15 -> 36461 | AF20: =+AF13+AF15 -> 53706 | AG20: =+AG13+AG15 -> 46284 | AH20: =+AH13+AH15 -> 35915 | AI20: =+AI13+AI15 -> 0 | ... AK20: =+AK13+AK15 -> 287513 | AL20: =+AK20/AK$13 -> 0.56182865 | AN20: =+AN13+AN15 -> 43545 | AO20: =+AO13+AO15 -> 31924 | AP20: =+AP13+AP15 -> 22603 | AQ20: =+AQ13+AQ15 -> 40496 | AR20: =+AR13+AR15 -> 54775 | AS20: =+AS13+AS15 -> 47973 | AT20: =+AT13+AT15 -> 37162 | AU20: =+AU13+AU15 -> 0 | ... AW20: =+AW13+AW15 -> 306431 | AX20: =+AW20/AW$13 -> 0.57705678 | AZ20: =+AZ13+AZ15 -> 35361 | BA20: =+BA13+BA15 -> 30151 | BB20: =+BB13+BB15 -> 21796 | BC20: =+BC13+BC15 -> 36952 | BD20: =+BD13+BD15 -> 56631 | BE20: =+BE13+BE15 -> 45456 | BF20: =+BF13+BF15 -> 33834 | BG20: =+BG13+BG15 -> 0 | ... BI20: =+BI13+BI15 -> 281496 | BJ20: =+BI20/BI$13 -> 0.56759634 | BL20: =+BL13+BL15 -> 33577 | BM20: =+BM13+BM15 -> 29431 | BN20: =+BN13+BN15 -> 20835 | BO20: =+BO13+BO15 -> 38417 | BP20: =+BP13+BP15 -> 60165 | BQ20: =+BQ13+BQ15 -> 44342 | BR20: =+BR13+BR15 -> 33509 | BS20: =+BS13+BS15 -> 0 | ... BU20: =+BU13+BU15 -> 286283 | BV20: =+BU20/BU$13 -> 0.57593638 | BX20: =+BX13+BX15 -> 37603 | BY20: =+BY13+BY15 -> 30157 | BZ20: =+BZ13+BZ15 -> 20545 | CA20: =+CA13+CA15 -> 39758 | CB20: =+CB13+CB15 -> 48840 | CC20: =+CC13+CC15 -> 44657 | CD20: =+CD13+CD15 -> 31931 | CE20: =+CE13+CE15 -> 0 | ... CG20: =+CG13+CG15 -> 280129 | CH20: =+CG20/CG$13 -> 0.58361667 | CJ20: =+CG20-BU20 -> -6154 | CK20: =IFERROR(+CJ20/BU20,0%) -> -0.021496212 | CM20: =+CM13+CM15 -> 1762927.5 | CN20: =+CM20/CM$13 -> 0.57951661 | CP20: =+CP13+CP15 -> 293380.5 | CQ20: =+CP20/CP$13 -> 0.5694536 | CS20: =+CS13+CS15 -> 1697868.5 | CT20: =+CS20/CS$13 -> 0.57771606 | CV20: =+CM20-CS20 -> 65059 | CW20: =+IFERROR(CV20/CS20,0) -> 0.038318044
B22: Otros Ingresos | D22: =+SUM(D25:D31) -> 35 | E22: =+SUM(E25:E31) -> 44 | F22: =+SUM(F25:F31) -> 65 | G22: =+SUM(G25:G31) -> 237 | H22: =+SUM(H25:H31) -> 6526 | I22: =+SUM(I25:I31) -> 209 | J22: =+SUM(J25:J31) -> 63 | K22: =+SUM(K25:K31) -> 0 | ... M22: =+SUM(M25:M31) -> 7249 | N22: =+M22/M$13 -> 0.014361025 | P22: =+SUM(P23:P31) -> 41 | Q22: =+SUM(Q23:Q31) -> 118 | R22: =+SUM(R23:R31) -> 18 | S22: =+SUM(S23:S31) -> 50 | T22: =+SUM(T23:T31) -> 7422 | U22: =+SUM(U23:U31) -> 178 | V22: =+SUM(V23:V31) -> 81 | W22: =+SUM(W23:W31) -> 2406 | ... Y22: =+SUM(Y23:Y31) -> 10375 | Z22: =+Y22/Y$13 -> 0.019713766 | AB22: =+SUM(AB23:AB31) -> 15 | AC22: =+SUM(AC23:AC31) -> 125 | AD22: =+SUM(AD23:AD31) -> 37 | AE22: =+SUM(AE23:AE31) -> 69 | AF22: =+SUM(AF23:AF31) -> 5162 | AG22: =+SUM(AG23:AG31) -> 295 | AH22: =+SUM(AH23:AH31) -> 106 | AI22: =+SUM(AI23:AI31) -> 0 | ... AK22: =+SUM(AK23:AK31) -> 5859 | AL22: =+AK22/AK$13 -> 0.011449062 | AN22: =+SUM(AN23:AN31) -> 81 | AO22: =+SUM(AO23:AO31) -> 156 | AP22: =+SUM(AP23:AP31) -> 74 | AQ22: =+SUM(AQ23:AQ31) -> 37 | AR22: =+SUM(AR23:AR31) -> 1013 | AS22: =+SUM(AS23:AS31) -> 58 | AT22: =+SUM(AT23:AT31) -> 63 | AU22: =+SUM(AU23:AU31) -> 6220 | ... AW22: =+SUM(AW23:AW31) -> 7812 | AX22: =+AW22/AW$13 -> 0.014711199 | AZ22: =+SUM(AZ23:AZ31) -> 108 | BA22: =+SUM(BA23:BA31) -> 692 | BB22: =+SUM(BB23:BB31) -> 98 | BC22: =+SUM(BC23:BC31) -> 105 | BD22: =+SUM(BD23:BD31) -> 1005 | BE22: =+SUM(BE23:BE31) -> 118 | BF22: =+SUM(BF23:BF31) -> 91 | BG22: =+SUM(BG23:BG31) -> 7620 | ... BI22: =+SUM(BI23:BI31) -> 9958 | BJ22: =+BI22/BI$13 -> 0.02007888 | BL22: =+SUM(BL23:BL31) -> 405 | BM22: =+SUM(BM23:BM31) -> 38 | BN22: =+SUM(BN23:BN31) -> 32 | BO22: =+SUM(BO23:BO31) -> 167 | BP22: =+SUM(BP23:BP31) -> 1073 | BQ22: =+SUM(BQ23:BQ31) -> 62 | BR22: =+SUM(BR23:BR31) -> 698 | BS22: =+SUM(BS23:BS31) -> 9246 | ... BU22: =+SUM(BU23:BU31) -> 11733 | BV22: =+BU22/BU$13 -> 0.023604131 | BX22: =+SUM(BX23:BX31) -> 12 | BY22: =+SUM(BY23:BY31) -> 35 | BZ22: =+SUM(BZ23:BZ31) -> 97 | CA22: =+SUM(CA23:CA31) -> 167 | CB22: =+SUM(CB23:CB31) -> 966 | CC22: =+SUM(CC23:CC31) -> 107 | CD22: =+SUM(CD23:CD31) -> 161 | CE22: =+SUM(CE23:CE31) -> 9133 | ... CG22: =+SUM(CG23:CG31) -> 10756 | CH22: =+CG22/CG$13 -> 0.022408894 | CJ22: =+CG22-BU22 -> -977 | CK22: =IFERROR(+CJ22/BU22,0%) -> -0.083269411 | CM22: =+SUM(CM23:CM31) -> 56493 | CN22: =+CM22/CM$13 -> 0.018570606 | CP22: =+SUM(CP25:CP31) -> 1944 | CQ22: =+CP22/CP$13 -> 0.0037733176 | CS22: =+SUM(CS25:CS31) -> 9959 | CT22: =+CS22/CS$13 -> 0.0033886454 | CV22: =+CM22-CS22 -> 46534 | CW22: =+IFERROR(CV22/CS22,0) -> 4.6725575
A23: 4220 | B23: Ingresos por arrendamientos | P23: 0 | Q23: 0 | R23: 0 | S23: 0 | T23: 0 | U23: 0 | V23: 0 | W23: 2406 | X23: 0 | Y23: =SUM(P23:X23) -> 2406 | Z23: =+Y23/Y$13 -> 0.0045716935 | AB23: 0 | AC23: 0 | AD23: 0 | AE23: 0 | AF23: 0 | AG23: 0 | AH23: 0 | AI23: 0 | AJ23: 0 | AK23: =SUM(AB23:AJ23) -> 0 | AL23: =+AK23/AK$13 -> 0 | AN23: 0 | AO23: 0 | AP23: 0 | AQ23: 0 | AR23: 0 | AS23: 0 | AT23: 0 | AU23: 6220 | AV23: 0 | AW23: =SUM(AN23:AV23) -> 6220 | AX23: =+AW23/AW$13 -> 0.011713218 | AZ23: 0 | BA23: 0 | BB23: 0 | BC23: 0 | BD23: 0 | BE23: 0 | BF23: 0 | BG23: 7620 | BH23: 0 | BI23: =SUM(AZ23:BH23) -> 7620 | BJ23: =+BI23/BI$13 -> 0.015364638 | BL23: 0 | BM23: 0 | BN23: 0 | BO23: 0 | BP23: 0 | BQ23: 0 | BR23: 0 | BS23: 9246 | BT23: 0 | BU23: =SUM(BL23:BT23) -> 9246 | BV23: =+BU23/BU$13 -> 0.018600852 | BX23: 0 | BY23: 0 | BZ23: 0 | CA23: 0 | CB23: 0 | CC23: 0 | CD23: 0 | CE23: 9133 | CF23: 0 | CG23: =SUM(BX23:CF23) -> 9133 | CH23: =+CG23/CG$13 -> 0.019027559 | CJ23: =+CG23-BU23 -> -113 | CK23: =IFERROR(+CJ23/BU23,0%) -> -0.012221501 | CM23: =+Y23+AK23+CG23+AW23+BI23+BU23 -> 34625 | CN23: =+CM23/CM$13 -> 0.011382069
A24: 42358001 | B24: Servicios Fletes | P24: 0 | Q24: 0 | R24: 0 | S24: 0 | T24: 899 | U24: 0 | V24: 0 | W24: 0 | X24: 0 | Y24: =SUM(P24:X24) -> 899 | Z24: =+Y24/Y$13 -> 0.0017082097 | AB24: 0 | AC24: 0 | AD24: 0 | AE24: 0 | AF24: 899 | AG24: 0 | AH24: 0 | AI24: 0 | AJ24: 0 | AK24: =SUM(AB24:AJ24) -> 899 | AL24: =+AK24/AK$13 -> 0.0017567343 | AN24: 0 | AO24: 0 | AP24: 0 | AQ24: 0 | AR24: 0 | AS24: 0 | AT24: 0 | AU24: 0 | AV24: 0 | AW24: =SUM(AN24:AV24) -> 0 | AX24: =+AW24/AW$13 -> 0 | AZ24: 0 | BA24: 0 | BB24: 0 | BC24: 0 | BD24: 0 | BE24: 0 | BF24: 0 | BG24: 0 | BH24: 0 | BI24: =SUM(AZ24:BH24) -> 0 | BJ24: =+BI24/BI$13 -> 0 | BL24: 0 | BM24: 0 | BN24: 0 | BO24: 0 | BP24: 0 | BQ24: 0 | BR24: 0 | BS24: 0 | BT24: 0 | BU24: =SUM(BL24:BT24) -> 0 | BV24: =+BU24/BU$13 -> 0 | BX24: 0 | BY24: 0 | BZ24: 0 | CA24: 0 | CB24: 0 | CC24: 0 | CD24: 0 | CE24: 0 | CF24: 0 | CG24: =SUM(BX24:CF24) -> 0 | CH24: =+CG24/CG$13 -> 0 | CJ24: =+CG24-BU24 -> 0 | CK24: =IFERROR(+CJ24/BU24,0%) -> 0 | CM24: =+Y24+AK24+CG24+AW24+BI24+BU24 -> 1798 | CN24: =+CM24/CM$13 -> 0.00059104579
A25: 42359604 | B25: Servicios | D25: 0 | E25: 0 | F25: 0 | G25: 0 | H25: 6462 | I25: 0 | J25: 0 | K25: 0 | L25: 0 | M25: =SUM(D25:L25) -> 6462 | N25: =+M25/M$13 -> 0.012801896 | P25: 0 | Q25: 0 | R25: 0 | S25: 0 | T25: 6354 | U25: 0 | V25: 0 | W25: 0 | X25: 0 | Y25: =SUM(P25:X25) -> 6354 | Z25: =+Y25/Y$13 -> 0.012073375 | AB25: 0 | AC25: 0 | AD25: 0 | AE25: 0 | AF25: 4222 | AG25: 0 | AH25: 0 | AI25: 0 | AJ25: 0 | AK25: =SUM(AB25:AJ25) -> 4222 | AL25: =+AK25/AK$13 -> 0.0082502027 | AN25: 0 | AO25: 0 | AP25: 0 | AQ25: 0 | AR25: 899 | AS25: 0 | AT25: 0 | AU25: 0 | AV25: 0 | AW25: =SUM(AN25:AV25) -> 899 | AX25: =+AW25/AW$13 -> 0.0016929555 | AZ25: 0 | BA25: 0 | BB25: 0 | BC25: 0 | BD25: 899 | BE25: 0 | BF25: 0 | BG25: 0 | BH25: 104 | BI25: =SUM(AZ25:BH25) -> 1003 | BJ25: =+BI25/BI$13 -> 0.0020224058 | BL25: 0 | BM25: 0 | BN25: 0 | BO25: 0 | BP25: 990 | BQ25: 0 | BR25: 627 | BS25: 0 | BT25: 0 | BU25: =SUM(BL25:BT25) -> 1617 | BV25: =+BU25/BU$13 -> 0.0032530368 | BX25: 0 | BY25: 0 | BZ25: 0 | CA25: 0 | CB25: 899 | CC25: 0 | CD25: 0 | CE25: 0 | CF25: 0 | CG25: =SUM(BX25:CF25) -> 899 | CH25: =+CG25/CG$13 -> 0.0018729635 | CJ25: =+CG25-BU25 -> -718 | CK25: =IFERROR(+CJ25/BU25,0%) -> -0.44403216 | CM25: =+Y25+AK25+CG25+AW25+BI25+BU25 -> 14994 | CN25: =+CM25/CM$13 -> 0.004928888 | CP25: =+DATOS!F99 -> 1421 | CQ25: =+CP25/CP$13 -> 0.0027581709 | CS25: =+DATOS!G99 -> 4161 | CT25: =+CS25/CS$13 -> 0.0014158202 | CV25: =+CM25-CS25 -> 10833 | CW25: =+IFERROR(CV25/CS25,0) -> 2.6034607
A26: 42505001 | B26: Recuperacion de costos y gastos | D26: 0 | E26: 0 | F26: 0 | G26: 0 | H26: 0 | I26: 0 | J26: 0 | K26: 0 | L26: 0 | M26: =SUM(D26:L26) -> 0 | N26: =+M26/M$13 -> 0 | P26: 0 | Q26: 0 | R26: 0 | S26: 0 | T26: 0 | U26: 0 | V26: 0 | W26: 0 | X26: 0 | Y26: =SUM(P26:X26) -> 0 | Z26: =+Y26/Y$13 -> 0 | AB26: 0 | AC26: 0 | AD26: 0 | AE26: 0 | AF26: 0 | AG26: 0 | AH26: 0 | AI26: 0 | AJ26: 0 | AK26: =SUM(AB26:AJ26) -> 0 | AL26: =+AK26/AK$13 -> 0 | AN26: 0 | AO26: 0 | AP26: 0 | AQ26: 0 | AR26: 0 | AS26: 0 | AT26: 0 | AU26: 0 | AV26: 0 | AW26: =SUM(AN26:AV26) -> 0 | AX26: =+AW26/AW$13 -> 0 | AZ26: 0 | BA26: 0 | BB26: 0 | BC26: 0 | BD26: 0 | BE26: 0 | BF26: 0 | BG26: 0 | BH26: 0 | BI26: =SUM(AZ26:BH26) -> 0 | BJ26: =+BI26/BI$13 -> 0 | BL26: 0 | BM26: 0 | BN26: 0 | BO26: 0 | BP26: 0 | BQ26: 0 | BR26: 0 | BS26: 0 | BT26: 0 | BU26: =SUM(BL26:BT26) -> 0 | BV26: =+BU26/BU$13 -> 0 | BX26: 0 | BY26: 0 | BZ26: 0 | CA26: 0 | CB26: 0 | CC26: 0 | CD26: 0 | CE26: 0 | CF26: 0 | CG26: =SUM(BX26:CF26) -> 0 | CH26: =+CG26/CG$13 -> 0 | CJ26: =+CG26-BU26 -> 0 | CK26: =IFERROR(+CJ26/BU26,0%) -> 0 | CM26: =+Y26+AK26+CG26+AW26+BI26+BU26 -> 0 | CN26: =+CM26/CM$13 -> 0 | CP26: =+DATOS!F101 -> 4 | CQ26: =+CP26/CP$13 -> 7.7640279e-06 | CT26: =+CS26/CS$13 -> 0 | CV26: =+CM26-CS26 -> 0 | CW26: =+IFERROR(CV26/CS26,0) -> 0
A27: 42505003 | B27: Ded. Alimentancion empleados | D27: 0 | E27: 0 | F27: 0 | G27: 0 | H27: 1 | I27: 0 | J27: 3 | K27: 0 | L27: 0 | M27: =SUM(D27:L27) -> 4 | N27: =+M27/M$13 -> 7.9244169e-06 | P27: 0 | Q27: 0 | R27: 0 | S27: 0 | T27: 1 | U27: 0 | V27: 3 | W27: 0 | X27: 0 | Y27: =SUM(P27:X27) -> 4 | Z27: =+Y27/Y$13 -> 7.600488e-06 | AB27: 0 | AC27: 0 | AD27: 0 | AE27: 0 | AF27: 1 | AG27: 0 | AH27: 3 | AI27: 0 | AJ27: 0 | AK27: =SUM(AB27:AJ27) -> 4 | AL27: =+AK27/AK$13 -> 7.8163929e-06 | AN27: 0 | AO27: 0 | AP27: 0 | AQ27: 0 | AR27: 1 | AS27: 0 | AT27: 3 | AU27: 0 | AV27: 0 | AW27: =SUM(AN27:AV27) -> 4 | AX27: =+AW27/AW$13 -> 7.5326162e-06 | AZ27: 0 | BA27: 0 | BB27: 0 | BC27: 0 | BD27: 1 | BE27: 0 | BF27: 3 | BG27: 0 | BH27: 0 | BI27: =SUM(AZ27:BH27) -> 4 | BJ27: =+BI27/BI$13 -> 8.0654267e-06 | BL27: 0 | BM27: 0 | BN27: 0 | BO27: 0 | BP27: 1 | BQ27: 0 | BR27: 3 | BS27: 0 | BT27: 0 | BU27: =SUM(BL27:BT27) -> 4 | BV27: =+BU27/BU$13 -> 8.0470916e-06 | BX27: 0 | BY27: 0 | BZ27: 0 | CA27: 0 | CB27: 1 | CC27: 0 | CD27: 3 | CE27: 0 | CF27: 0 | CG27: =SUM(BX27:CF27) -> 4 | CH27: =+CG27/CG$13 -> 8.3335417e-06 | CJ27: =+CG27-BU27 -> 0 | CK27: =IFERROR(+CJ27/BU27,0%) -> 0 | CM27: =+Y27+AK27+CG27+AW27+BI27+BU27 -> 24 | CN27: =+CM27/CM$13 -> 7.8893765e-06 | CP27: 0 | CQ27: =+CP27/CP$13 -> 0 | CS27: =+DATOS!G101 -> 20 | CT27: =+CS27/CS$13 -> 6.805192e-06 | CV27: =+CM27-CS27 -> 4 | CW27: =+IFERROR(CV27/CS27,0) -> 0.2
A28: 42554001 | B28: Indemnizaciones (incapacidades) | D28: 0 | E28: 0 | F28: 0 | G28: 0 | H28: 0 | I28: 0 | J28: 0 | K28: 0 | L28: 0 | M28: =SUM(D28:L28) -> 0 | N28: =+M28/M$13 -> 0 | P28: 0 | Q28: 0 | R28: 0 | S28: 0 | T28: 0 | U28: 0 | V28: 0 | W28: 0 | X28: 0 | Y28: =SUM(P28:X28) -> 0 | Z28: =+Y28/Y$13 -> 0 | AB28: 0 | AC28: 0 | AD28: 0 | AE28: 0 | AF28: 0 | AG28: 0 | AH28: 0 | AI28: 0 | AJ28: 0 | AK28: =SUM(AB28:AJ28) -> 0 | AL28: =+AK28/AK$13 -> 0 | AN28: 0 | AO28: 47 | AP28: 0 | AQ28: 0 | AR28: 0 | AS28: 0 | AT28: 0 | AU28: 0 | AV28: 0 | AW28: =SUM(AN28:AV28) -> 47 | AX28: =+AW28/AW$13 -> 8.8508241e-05 | AZ28: 0 | BA28: 226 | BB28: 0 | BC28: 0 | BD28: 0 | BE28: 0 | BF28: 0 | BG28: 0 | BH28: 0 | BI28: =SUM(AZ28:BH28) -> 226 | BJ28: =+BI28/BI$13 -> 0.00045569661 | BL28: 332 | BM28: 0 | BN28: 0 | BO28: 0 | BP28: 0 | BQ28: 0 | BR28: 0 | BS28: 0 | BT28: 0 | BU28: =SUM(BL28:BT28) -> 332 | BV28: =+BU28/BU$13 -> 0.0006679086 | BX28: 0 | BY28: 0 | BZ28: 0 | CA28: 0 | CB28: 0 | CC28: 0 | CD28: 0 | CE28: 0 | CF28: 0 | CG28: =SUM(BX28:CF28) -> 0 | CH28: =+CG28/CG$13 -> 0 | CJ28: =+CG28-BU28 -> -332 | CK28: =IFERROR(+CJ28/BU28,0%) -> -1 | CM28: =+Y28+AK28+CG28+AW28+BI28+BU28 -> 605 | CN28: =+CM28/CM$13 -> 0.00019887803 | CP28: =+DATOS!F102 -> 0 | CQ28: =+CP28/CP$13 -> 0 | CS28: =+DATOS!G102 -> 1051 | CT28: =+CS28/CS$13 -> 0.00035761284 | CV28: =+CM28-CS28 -> -446 | CW28: =+IFERROR(CV28/CS28,0) -> -0.42435775
A29: 42950501 | B29: Aprovechamientos | D29: 0 | E29: 0 | F29: 22 | G29: 0 | H29: 0 | I29: 0 | J29: 0 | K29: 0 | L29: 0 | M29: =SUM(D29:L29) -> 22 | N29: =+M29/M$13 -> 4.3584293e-05 | P29: 0 | Q29: 0 | R29: 0 | S29: 0 | T29: 0 | U29: 0 | V29: 0 | W29: 0 | X29: 0 | Y29: =SUM(P29:X29) -> 0 | Z29: =+Y29/Y$13 -> 0 | AB29: 0 | AC29: 0 | AD29: 8 | AE29: 0 | AF29: 0 | AG29: 0 | AH29: 0 | AI29: 0 | AJ29: 0 | AK29: =SUM(AB29:AJ29) -> 8 | AL29: =+AK29/AK$13 -> 1.5632786e-05 | AN29: 0 | AO29: 0 | AP29: 0 | AQ29: 0 | AR29: 0 | AS29: 0 | AT29: 0 | AU29: 0 | AV29: 0 | AW29: =SUM(AN29:AV29) -> 0 | AX29: =+AW29/AW$13 -> 0 | AZ29: 0 | BA29: 400 | BB29: 30 | BC29: 0 | BD29: 0 | BE29: 0 | BF29: 0 | BG29: 0 | BH29: 0 | BI29: =SUM(AZ29:BH29) -> 430 | BJ29: =+BI29/BI$13 -> 0.00086703337 | BL29: 0 | BM29: 0 | BN29: 0 | BO29: 0 | BP29: 0 | BQ29: 0 | BR29: 0 | BS29: 0 | BT29: 0 | BU29: =SUM(BL29:BT29) -> 0 | BV29: =+BU29/BU$13 -> 0 | BX29: 0 | BY29: 0 | BZ29: 42 | CA29: 0 | CB29: 35 | CC29: 0 | CD29: 0 | CE29: 0 | CF29: 0 | CG29: =SUM(BX29:CF29) -> 77 | CH29: =+CG29/CG$13 -> 0.00016042068 | CJ29: =+CG29-BU29 -> 77 | CK29: =IFERROR(+CJ29/BU29,0%) -> 0 | CM29: =+Y29+AK29+CG29+AW29+BI29+BU29 -> 515 | CN29: =+CM29/CM$13 -> 0.00016929287 | CP29: 0 | CQ29: =+CP29/CP$13 -> 0 | CS29: 0 | CT29: =+CS29/CS$13 -> 0 | CV29: =+CM29-CS29 -> 515 | CW29: =+IFERROR(CV29/CS29,0) -> 0
A30: 42951601 | B30: Sobrantes de caja | D30: 35 | E30: 44 | F30: 43 | G30: 236 | H30: 63 | I30: 209 | J30: 60 | K30: 0 | L30: 70 | M30: =SUM(D30:L30) -> 760 | N30: =+M30/M$13 -> 0.0015056392 | P30: 41 | Q30: 118 | R30: 18 | S30: 50 | T30: 168 | U30: 178 | V30: 78 | W30: 0 | X30: 61 | Y30: =SUM(P30:X30) -> 712 | Z30: =+Y30/Y$13 -> 0.0013528869 | AB30: 15 | AC30: 125 | AD30: 29 | AE30: 69 | AF30: 40 | AG30: 295 | AH30: 102 | AI30: 0 | AJ30: 50 | AK30: =SUM(AB30:AJ30) -> 725 | AL30: =+AK30/AK$13 -> 0.0014167212 | AN30: 81 | AO30: 109 | AP30: 74 | AQ30: 37 | AR30: 113 | AS30: 58 | AT30: 59 | AU30: 0 | AV30: 110 | AW30: =SUM(AN30:AV30) -> 641 | AX30: =+AW30/AW$13 -> 0.0012071018 | AZ30: 108 | BA30: 66 | BB30: 68 | BC30: 105 | BD30: 105 | BE30: 118 | BF30: 88 | BG30: 0 | BH30: 17 | BI30: =SUM(AZ30:BH30) -> 675 | BJ30: =+BI30/BI$13 -> 0.0013610408 | BL30: 73 | BM30: 38 | BN30: 32 | BO30: 167 | BP30: 82 | BQ30: 62 | BR30: 68 | BS30: 0 | BT30: 12 | BU30: =SUM(BL30:BT30) -> 534 | BV30: =+BU30/BU$13 -> 0.0010742867 | BX30: 12 | BY30: 35 | BZ30: 55 | CA30: 167 | CB30: 31 | CC30: 107 | CD30: 158 | CE30: 0 | CF30: 78 | CG30: =SUM(BX30:CF30) -> 643 | CH30: =+CG30/CG$13 -> 0.0013396168 | CJ30: =+CG30-BU30 -> 109 | CK30: =IFERROR(+CJ30/BU30,0%) -> 0.20411985 | CM30: =+Y30+AK30+CG30+AW30+BI30+BU30 -> 3930 | CN30: =+CM30/CM$13 -> 0.0012918854 | CP30: 0 | CQ30: =+CP30/CP$13 -> 0 | CT30: =+CS30/CS$13 -> 0 | CV30: =+CM30-CS30 -> 3930 | CW30: =+IFERROR(CV30/CS30,0) -> 0
A31: 42958101 | B31: Ajuste Al Peso | D31: 0 | E31: 0 | F31: 0 | G31: 1 | H31: 0 | I31: 0 | J31: 0 | K31: 0 | L31: 0 | M31: =SUM(D31:L31) -> 1 | N31: =+M31/M$13 -> 1.9811042e-06 | P31: 0 | Q31: 0 | R31: 0 | S31: 0 | T31: 0 | U31: 0 | V31: 0 | W31: 0 | X31: 0 | Y31: =SUM(P31:X31) -> 0 | Z31: =+Y31/Y$13 -> 0 | AB31: 0 | AC31: 0 | AD31: 0 | AE31: 0 | AF31: 0 | AG31: 0 | AH31: 1 | AI31: 0 | AJ31: 0 | AK31: =SUM(AB31:AJ31) -> 1 | AL31: =+AK31/AK$13 -> 1.9540982e-06 | AN31: 0 | AO31: 0 | AP31: 0 | AQ31: 0 | AR31: 0 | AS31: 0 | AT31: 1 | AU31: 0 | AV31: 0 | AW31: =SUM(AN31:AV31) -> 1 | AX31: =+AW31/AW$13 -> 1.8831541e-06 | AZ31: 0 | BA31: 0 | BB31: 0 | BC31: 0 | BD31: 0 | BE31: 0 | BF31: 0 | BG31: 0 | BH31: 0 | BI31: =SUM(AZ31:BH31) -> 0 | BJ31: =+BI31/BI$13 -> 0 | BL31: 0 | BM31: 0 | BN31: 0 | BO31: 0 | BP31: 0 | BQ31: 0 | BR31: 0 | BS31: 0 | BT31: 0 | BU31: =SUM(BL31:BT31) -> 0 | BV31: =+BU31/BU$13 -> 0 | BX31: 0 | BY31: 0 | BZ31: 0 | CA31: 0 | CB31: 0 | CC31: 0 | CD31: 0 | CE31: 0 | CF31: 0 | CG31: =SUM(BX31:CF31) -> 0 | CH31: =+CG31/CG$13 -> 0 | CJ31: =+CG31-BU31 -> 0 | CK31: =IFERROR(+CJ31/BU31,0%) -> 0 | CM31: =+Y31+AK31+CG31+AW31+BI31+BU31 -> 2 | CN31: =+CM31/CM$13 -> 6.5744804e-07 | CP31: =+DATOS!F104 -> 519 | CQ31: =+CP31/CP$13 -> 0.0010073826 | CS31: =+DATOS!G104 -> 4727 | CT31: =+CS31/CS$13 -> 0.0016084071 | CV31: =+CM31-CS31 -> -4725 | CW31: =+IFERROR(CV31/CS31,0) -> -0.9995769
